Workbook

Sheet จองคิว
A1: เดือน | B1: วัน | C1: นัดหมาย | D1: Job No. | E1: สถานะ | F1: รหัสเครื่อง | G1: ชื่อเครื่อง | H1: ยี่ห้อ | I1: รุ่น | J1: SerialNo | K1: หน่วยงานผู้ใช้ | L1: งาน | M1: ผู้รับจอง | N1: หมายเหตุ
A2: =TEXT(C2, "mmm") -> ก.ย. | B2: =TEXT(C2,"[$-41E]dddd") -> พุธ | C2: 46267 | D2: 69-15479 | E2: แล้วเสร็จ | F2: MEDCMU-008036 | G2: =INDEX('เครื่องมือแพทย์ (956)'!$C:$C,MATCH(F2,'เครื่องมือแพทย์ (956)'!$B:$B,0)) -> Vital Sign Monitors | H2: =INDEX('เครื่องมือแพทย์ (956)'!$E:$E,MATCH(F2,'เครื่องมือแพทย์ (956)'!$B:$B,0)) -> CSI Criticare | I2: =INDEX('เครื่องมือแพทย์ (956)'!$F:$F,MATCH(F2,'เครื่องมือแพทย์ (956)'!$B:$B,0)) -> eQuality 506DN | J2: =INDEX('เครื่องมือแพทย์ (956)'!$G:$G,MATCH(F2,'เครื่องมือแพทย์ (956)'!$B:$B,0)) -> 113054300 | K2: =INDEX('เครื่องมือแพทย์ (956)'!$J:$J,MATCH(F2,'เครื่องมือแพทย์ (956)'!$B:$B,0)) -> หอผู้ป่วยฟื้นฟูสภาพ | L2: =INDEX('เครื่องมือแพทย์ (956)'!$K:$K,MATCH(F2,'เครื่องมือแพทย์ (956)'!$B:$B,0)) -> งานการพยาบาลผู้ป่วยทั่วไป จิตเวช จักษุและโสต ศอ นาสิก | M2: น้ำ
A3: =TEXT(C3, "mmm") -> ก.ย. | B3: =TEXT(C3,"[$-41E]dddd") -> พุธ | C3: 46267 | D3: 69-15428 | E3: แล้วเสร็จ | F3: MEDCMU-008037 | G3: =INDEX('เครื่องมือแพทย์ (956)'!$C:$C,MATCH(F3,'เครื่องมือแพทย์ (956)'!$B:$B,0)) -> Vital Sign Monitors | H3: =INDEX('เครื่องมือแพทย์ (956)'!$E:$E,MATCH(F3,'เครื่องมือแพทย์ (956)'!$B:$B,0)) -> CSI Criticare | I3: =INDEX('เครื่องมือแพทย์ (956)'!$F:$F,MATCH(F3,'เครื่องมือแพทย์ (956)'!$B:$B,0)) -> eQuality 506DN | J3: =INDEX('เครื่องมือแพทย์ (956)'!$G:$G,MATCH(F3,'เครื่องมือแพทย์ (956)'!$B:$B,0)) -> 113054315 | K3: =INDEX('เครื่องมือแพทย์ (956)'!$J:$J,MATCH(F3,'เครื่องมือแพทย์ (956)'!$B:$B,0)) -> หอผู้ป่วยฟื้นฟูสภาพ | L3: =INDEX('เครื่องมือแพทย์ (956)'!$K:$K,MATCH(F3,'เครื่องมือแพทย์ (956)'!$B:$B,0)) -> งานการพยาบาลผู้ป่วยทั่วไป จิตเวช จักษุและโสต ศอ นาสิก | M3: น้ำ
A4: =TEXT(C4, "mmm") -> ก.ย. | B4: =TEXT(C4,"[$-41E]dddd") -> พุธ | C4: 46267 | D4: 69-15427 | E4: แล้วเสร็จ | F4: MEDCMU-008102 | G4: =INDEX('เครื่องมือแพทย์ (956)'!$C:$C,MATCH(F4,'เครื่องมือแพทย์ (956)'!$B:$B,0)) -> Electrocardiography | H4: =INDEX('เครื่องมือแพทย์ (956)'!$E:$E,MATCH(F4,'เครื่องมือแพทย์ (956)'!$B:$B,0)) -> Fukuda Denshi | I4: =INDEX('เครื่องมือแพทย์ (956)'!$F:$F,MATCH(F4,'เครื่องมือแพทย์ (956)'!$B:$B,0)) -> FX-2111 | J4: =INDEX('เครื่องมือแพทย์ (956)'!$G:$G,MATCH(F4,'เครื่องมือแพทย์ (956)'!$B:$B,0)) -> 3415-3053 | K4: =INDEX('เครื่องมือแพทย์ (956)'!$J:$J,MATCH(F4,'เครื่องมือแพทย์ (956)'!$B:$B,0)) -> หอผู้ป่วยฟื้นฟูสภาพ | L4: =INDEX('เครื่องมือแพทย์ (956)'!$K:$K,MATCH(F4,'เครื่องมือแพทย์ (956)'!$B:$B,0)) -> งานการพยาบาลผู้ป่วยทั่วไป จิตเวช จักษุและโสต ศอ นาสิก | M4: น้ำ
A5: =TEXT(C5, "mmm") -> ก.ย. | B5: =TEXT(C5,"[$-41E]dddd") -> พุธ | C5: 46267 | D5: 69-15464 | E5: แล้วเสร็จ | F5: MEDCMU-008131 | G5: =INDEX('เครื่องมือแพทย์ (956)'!$C:$C,MATCH(F5,'เครื่องมือแพทย์ (956)'!$B:$B,0)) -> Vital Sign Monitors | H5: =INDEX('เครื่องมือแพทย์ (956)'!$E:$E,MATCH(F5,'เครื่องมือแพทย์ (956)'!$B:$B,0)) -> Goldway | I5: =INDEX('เครื่องมือแพทย์ (956)'!$F:$F,MATCH(F5,'เครื่องมือแพทย์ (956)'!$B:$B,0)) -> G30E | J5: =INDEX('เครื่องมือแพทย์ (956)'!$G:$G,MATCH(F5,'เครื่องมือแพทย์ (956)'!$B:$B,0)) -> CN93909834 | K5: =INDEX('เครื่องมือแพทย์ (956)'!$J:$J,MATCH(F5,'เครื่องมือแพทย์ (956)'!$B:$B,0)) -> หอผู้ป่วยฟื้นฟูสภาพ | L5: =INDEX('เครื่องมือแพทย์ (956)'!$K:$K,MATCH(F5,'เครื่องมือแพทย์ (956)'!$B:$B,0)) -> งานการพยาบาลผู้ป่วยทั่วไป จิตเวช จักษุและโสต ศอ นาสิก | M5: น้ำ
A6: =TEXT(C6, "mmm") -> ก.ย. | B6: =TEXT(C6,"[$-41E]dddd") -> พุธ | C6: 46267 | D6: 69-15481 | E6: แล้วเสร็จ | F6: MEDCMU-020924 | G6: =INDEX('เครื่องมือแพทย์ (956)'!$C:$C,MATCH(F6,'เครื่องมือแพทย์ (956)'!$B:$B,0)) -> Pulse Oximeter | H6: =INDEX('เครื่องมือแพทย์ (956)'!$E:$E,MATCH(F6,'เครื่องมือแพทย์ (956)'!$B:$B,0)) -> ROSSMAX | I6: =INDEX('เครื่องมือแพทย์ (956)'!$F:$F,MATCH(F6,'เครื่องมือแพทย์ (956)'!$B:$B,0)) -> SA210 | J6: =INDEX('เครื่องมือแพทย์ (956)'!$G:$G,MATCH(F6,'เครื่องมือแพทย์ (956)'!$B:$B,0)) -> SP0905-00226 | K6: =INDEX('เครื่องมือแพทย์ (956)'!$J:$J,MATCH(F6,'เครื่องมือแพทย์ (956)'!$B:$B,0)) -> หน่วยกิจกรรมบำบัด | L6: =INDEX('เครื่องมือแพทย์ (956)'!$K:$K,MATCH(F6,'เครื่องมือแพทย์ (956)'!$B:$B,0)) -> ภาควิชาเวชศาสตร์ฟื้นฟู | M6: น้ำ
A7: =TEXT(C7, "mmm") -> ก.ย. | B7: =TEXT(C7,"[$-41E]dddd") -> พุธ | C7: 46267 | D7: 69-15468 | E7: แล้วเสร็จ | F7: MEDCMU-002499 | G7: =INDEX('เครื่องมือแพทย์ (956)'!$C:$C,MATCH(F7,'เครื่องมือแพทย์ (956)'!$B:$B,0)) -> Vital Sign Monitors | H7: =INDEX('เครื่องมือแพทย์ (956)'!$E:$E,MATCH(F7,'เครื่องมือแพทย์ (956)'!$B:$B,0)) -> Philips | I7: =INDEX('เครื่องมือแพทย์ (956)'!$F:$F,MATCH(F7,'เครื่องมือแพทย์ (956)'!$B:$B,0)) -> Efficia CM10 | J7: =INDEX('เครื่องมือแพทย์ (956)'!$G:$G,MATCH(F7,'เครื่องมือแพทย์ (956)'!$B:$B,0)) -> CN92383268 | K7: =INDEX('เครื่องมือแพทย์ (956)'!$J:$J,MATCH(F7,'เครื่องมือแพทย์ (956)'!$B:$B,0)) -> หอผู้ป่วยอายุรกรรมหญิง 2 | L7: =INDEX('เครื่องมือแพทย์ (956)'!$K:$K,MATCH(F7,'เครื่องมือแพทย์ (956)'!$B:$B,0)) -> งานการพยาบาลผู้ป่วยอายุรศาสตร์ | M7: ฝ้าย | N7: ส่งซ่อมต่อ
A8: =TEXT(C8, "mmm") -> ก.ย. | B8: =TEXT(C8,"[$-41E]dddd") -> พุธ | C8: 46267 | D8: 69-15466 | E8: แล้วเสร็จ | F8: MEDCMU-002502 | G8: =INDEX('เครื่องมือแพทย์ (956)'!$C:$C,MATCH(F8,'เครื่องมือแพทย์ (956)'!$B:$B,0)) -> Vital Sign Monitors | H8: =INDEX('เครื่องมือแพทย์ (956)'!$E:$E,MATCH(F8,'เครื่องมือแพทย์ (956)'!$B:$B,0)) -> Philips | I8: =INDEX('เครื่องมือแพทย์ (956)'!$F:$F,MATCH(F8,'เครื่องมือแพทย์ (956)'!$B:$B,0)) -> SureSigns VM4 | J8: =INDEX('เครื่องมือแพทย์ (956)'!$G:$G,MATCH(F8,'เครื่องมือแพทย์ (956)'!$B:$B,0)) -> US12558623 | K8: =INDEX('เครื่องมือแพทย์ (956)'!$J:$J,MATCH(F8,'เครื่องมือแพทย์ (956)'!$B:$B,0)) -> หอผู้ป่วยอายุรกรรมหญิง 2 | L8: =INDEX('เครื่องมือแพทย์ (956)'!$K:$K,MATCH(F8,'เครื่องมือแพทย์ (956)'!$B:$B,0)) -> งานการพยาบาลผู้ป่วยอายุรศาสตร์ | M8: ฝ้าย
A9: =TEXT(C9, "mmm") -> ก.ย. | B9: =TEXT(C9,"[$-41E]dddd") -> พุธ | C9: 46267 | D9: 69-15453 | E9: แล้วเสร็จ | F9: MEDCMU-018743 | G9: =INDEX('เครื่องมือแพทย์ (956)'!$C:$C,MATCH(F9,'เครื่องมือแพทย์ (956)'!$B:$B,0)) -> Vital Sign Monitors | H9: =INDEX('เครื่องมือแพทย์ (956)'!$E:$E,MATCH(F9,'เครื่องมือแพทย์ (956)'!$B:$B,0)) -> Creative Medical | I9: =INDEX('เครื่องมือแพทย์ (956)'!$F:$F,MATCH(F9,'เครื่องมือแพทย์ (956)'!$B:$B,0)) -> PC-900 | J9: =INDEX('เครื่องมือแพทย์ (956)'!$G:$G,MATCH(F9,'เครื่องมือแพทย์ (956)'!$B:$B,0)) -> J0100RJ03150 | K9: =INDEX('เครื่องมือแพทย์ (956)'!$J:$J,MATCH(F9,'เครื่องมือแพทย์ (956)'!$B:$B,0)) -> หอผู้ป่วยสังเกตอาการ | L9: =INDEX('เครื่องมือแพทย์ (956)'!$K:$K,MATCH(F9,'เครื่องมือแพทย์ (956)'!$B:$B,0)) -> งานการพยาบาลผู้ป่วยนอกและผู้ป่วยฉุกเฉิน | M9: น้ำ
A10: =TEXT(C10, "mmm") -> ก.ย. | B10: =TEXT(C10,"[$-41E]dddd") -> พุธ | C10: 46267 | D10: 69-15460 | E10: แล้วเสร็จ | F10: MEDCMU-013682 | G10: =INDEX('เครื่องมือแพทย์ (956)'!$C:$C,MATCH(F10,'เครื่องมือแพทย์ (956)'!$B:$B,0)) -> Pulse Oximeter | H10: =INDEX('เครื่องมือแพทย์ (956)'!$E:$E,MATCH(F10,'เครื่องมือแพทย์ (956)'!$B:$B,0)) -> Masimo | I10: =INDEX('เครื่องมือแพทย์ (956)'!$F:$F,MATCH(F10,'เครื่องมือแพทย์ (956)'!$B:$B,0)) -> Rad-5v | J10: =INDEX('เครื่องมือแพทย์ (956)'!$G:$G,MATCH(F10,'เครื่องมือแพทย์ (956)'!$B:$B,0)) -> N03621 | K10: =INDEX('เครื่องมือแพทย์ (956)'!$J:$J,MATCH(F10,'เครื่องมือแพทย์ (956)'!$B:$B,0)) -> ห้องตรวจเบอร์ 9 (ห้องตรวจอายุรกรรมทั่วไป) | L10: =INDEX('เครื่องมือแพทย์ (956)'!$K:$K,MATCH(F10,'เครื่องมือแพทย์ (956)'!$B:$B,0)) -> งานการพยาบาลผู้ป่วยนอกและผู้ป่วยฉุกเฉิน | M10: ฟิล์ม
A11: =TEXT(C11, "mmm") -> ก.ย. | B11: =TEXT(C11,"[$-41E]dddd") -> พุธ | C11: 46267 | D11: 69-15461 | E11: แล้วเสร็จ | F11: MEDCMU-013683 | G11: =INDEX('เครื่องมือแพทย์ (956)'!$C:$C,MATCH(F11,'เครื่องมือแพทย์ (956)'!$B:$B,0)) -> Pulse Oximeter | H11: =INDEX('เครื่องมือแพทย์ (956)'!$E:$E,MATCH(F11,'เครื่องมือแพทย์ (956)'!$B:$B,0)) -> Novametrix | I11: =INDEX('เครื่องมือแพทย์ (956)'!$F:$F,MATCH(F11,'เครื่องมือแพทย์ (956)'!$B:$B,0)) -> 125-18171MNPT | J11: =INDEX('เครื่องมือแพทย์ (956)'!$G:$G,MATCH(F11,'เครื่องมือแพทย์ (956)'!$B:$B,0)) -> UO-09-6649-001-9928/47(1) | K11: =INDEX('เครื่องมือแพทย์ (956)'!$J:$J,MATCH(F11,'เครื่องมือแพทย์ (956)'!$B:$B,0)) -> ห้องตรวจเบอร์ 9 (ห้องตรวจอายุรกรรมทั่วไป) | L11: =INDEX('เครื่องมือแพทย์ (956)'!$K:$K,MATCH(F11,'เครื่องมือแพทย์ (956)'!$B:$B,0)) -> งานการพยาบาลผู้ป่วยนอกและผู้ป่วยฉุกเฉิน | M11: ฟิล์ม
A12: =TEXT(C12, "mmm") -> ก.ย. | B12: =TEXT(C12,"[$-41E]dddd") -> พุธ | C12: 46267 | D12: 69-15465 | E12: แล้วเสร็จ | F12: MEDCMU-013856 | G12: =INDEX('เครื่องมือแพทย์ (956)'!$C:$C,MATCH(F12,'เครื่องมือแพทย์ (956)'!$B:$B,0)) -> Pulse Oximeter | H12: =INDEX('เครื่องมือแพทย์ (956)'!$E:$E,MATCH(F12,'เครื่องมือแพทย์ (956)'!$B:$B,0)) -> Mindray | I12: =INDEX('เครื่องมือแพทย์ (956)'!$F:$F,MATCH(F12,'เครื่องมือแพทย์ (956)'!$B:$B,0)) -> PM-60 | J12: =INDEX('เครื่องมือแพทย์ (956)'!$G:$G,MATCH(F12,'เครื่องมือแพทย์ (956)'!$B:$B,0)) -> CR-6B175995 | K12: =INDEX('เครื่องมือแพทย์ (956)'!$J:$J,MATCH(F12,'เครื่องมือแพทย์ (956)'!$B:$B,0)) -> ห้องตรวจเบอร์ 1(ห้องตรวจศัลยกรรม 1) | L12: =INDEX('เครื่องมือแพทย์ (956)'!$K:$K,MATCH(F12,'เครื่องมือแพทย์ (956)'!$B:$B,0)) -> งานการพยาบาลผู้ป่วยนอกและผู้ป่วยฉุกเฉิน | M12: ฟิล์ม
A13: =TEXT(C13, "mmm") -> ก.ย. | B13: =TEXT(C13,"[$-41E]dddd") -> พุธ | C13: 46267 | D13: 69-15463 | E13: แล้วเสร็จ | F13: MEDCMU-005628 | G13: =INDEX('เครื่องมือแพทย์ (956)'!$C:$C,MATCH(F13,'เครื่องมือแพทย์ (956)'!$B:$B,0)) -> Electrosurgical Unit | H13: =INDEX('เครื่องมือแพทย์ (956)'!$E:$E,MATCH(F13,'เครื่องมือแพทย์ (956)'!$B:$B,0)) -> Ellman | I13: =INDEX('เครื่องมือแพทย์ (956)'!$F:$F,MATCH(F13,'เครื่องมือแพทย์ (956)'!$B:$B,0)) -> Surgitron F.F.P.F. EMC | J13: =INDEX('เครื่องมือแพทย์ (956)'!$G:$G,MATCH(F13,'เครื่องมือแพทย์ (956)'!$B:$B,0)) -> 9130005990 | K13: =INDEX('เครื่องมือแพทย์ (956)'!$J:$J,MATCH(F13,'เครื่องมือแพทย์ (956)'!$B:$B,0)) -> ห้องตรวจเบอร์ 3 ( ห้องตรวจสูตินรีเวชกรรม) | L13: =INDEX('เครื่องมือแพทย์ (956)'!$K:$K,MATCH(F13,'เครื่องมือแพทย์ (956)'!$B:$B,0)) -> งานการพยาบาลผู้ป่วยนอกและผู้ป่วยฉุกเฉิน | M13: น้ำ
A14: =TEXT(C14, "mmm") -> ก.ย. | B14: =TEXT(C14,"[$-41E]dddd") -> พุธ | C14: 46267 | D14: 69-15510 | E14: แล้วเสร็จ | F14: MEDCMU-012119 | G14: =INDEX('เครื่องมือแพทย์ (956)'!$C:$C,MATCH(F14,'เครื่องมือแพทย์ (956)'!$B:$B,0)) -> Electrosurgical Unit | H14: =INDEX('เครื่องมือแพทย์ (956)'!$E:$E,MATCH(F14,'เครื่องมือแพทย์ (956)'!$B:$B,0)) -> Ellman | I14: =INDEX('เครื่องมือแพทย์ (956)'!$F:$F,MATCH(F14,'เครื่องมือแพทย์ (956)'!$B:$B,0)) -> Surgitron F.F.P.F. EMC | J14: =INDEX('เครื่องมือแพทย์ (956)'!$G:$G,MATCH(F14,'เครื่องมือแพทย์ (956)'!$B:$B,0)) -> 0006144 | K14: =INDEX('เครื่องมือแพทย์ (956)'!$J:$J,MATCH(F14,'เครื่องมือแพทย์ (956)'!$B:$B,0)) -> ห้องตรวจเบอร์ 26 (ห้องตรวจพิเศษอายุรกรรม 3) | L14: =INDEX('เครื่องมือแพทย์ (956)'!$K:$K,MATCH(F14,'เครื่องมือแพทย์ (956)'!$B:$B,0)) -> งานการพยาบาลผู้ป่วยนอกและผู้ป่วยฉุกเฉิน | M14: ฟิล์ม
A15: =TEXT(C15, "mmm") -> ก.ย. | B15: =TEXT(C15,"[$-41E]dddd") -> พุธ | C15: 46267 | D15: 69-15511 | E15: แล้วเสร็จ | F15: MEDCMU-012123 | G15: =INDEX('เครื่องมือแพทย์ (956)'!$C:$C,MATCH(F15,'เครื่องมือแพทย์ (956)'!$B:$B,0)) -> Pulse Oximeter | H15: =INDEX('เครื่องมือแพทย์ (956)'!$E:$E,MATCH(F15,'เครื่องมือแพทย์ (956)'!$B:$B,0)) -> Masimo | I15: =INDEX('เครื่องมือแพทย์ (956)'!$F:$F,MATCH(F15,'เครื่องมือแพทย์ (956)'!$B:$B,0)) -> Rad-5v | J15: =INDEX('เครื่องมือแพทย์ (956)'!$G:$G,MATCH(F15,'เครื่องมือแพทย์ (956)'!$B:$B,0)) -> N04027 | K15: =INDEX('เครื่องมือแพทย์ (956)'!$J:$J,MATCH(F15,'เครื่องมือแพทย์ (956)'!$B:$B,0)) -> ห้องตรวจเบอร์ 26 (ห้องตรวจพิเศษอายุรกรรม 3) | L15: =INDEX('เครื่องมือแพทย์ (956)'!$K:$K,MATCH(F15,'เครื่องมือแพทย์ (956)'!$B:$B,0)) -> งานการพยาบาลผู้ป่วยนอกและผู้ป่วยฉุกเฉิน | M15: ฟิล์ม
A16: =TEXT(C16, "mmm") -> ก.ย. | B16: =TEXT(C16,"[$-41E]dddd") -> พุธ | C16: 46267 | D16: 69-15512 | E16: แล้วเสร็จ | F16: MEDCMU-012132 | G16: =INDEX('เครื่องมือแพทย์ (956)'!$C:$C,MATCH(F16,'เครื่องมือแพทย์ (956)'!$B:$B,0)) -> Pulse Oximeter | H16: =INDEX('เครื่องมือแพทย์ (956)'!$E:$E,MATCH(F16,'เครื่องมือแพทย์ (956)'!$B:$B,0)) -> Bionics | I16: =INDEX('เครื่องมือแพทย์ (956)'!$F:$F,MATCH(F16,'เครื่องมือแพทย์ (956)'!$B:$B,0)) -> PalmCare Plus | J16: =INDEX('เครื่องมือแพทย์ (956)'!$G:$G,MATCH(F16,'เครื่องมือแพทย์ (956)'!$B:$B,0)) -> 161-RH5229 | K16: =INDEX('เครื่องมือแพทย์ (956)'!$J:$J,MATCH(F16,'เครื่องมือแพทย์ (956)'!$B:$B,0)) -> ห้องตรวจเบอร์ 26 (ห้องตรวจพิเศษอายุรกรรม 3) | L16: =INDEX('เครื่องมือแพทย์ (956)'!$K:$K,MATCH(F16,'เครื่องมือแพทย์ (956)'!$B:$B,0)) -> งานการพยาบาลผู้ป่วยนอกและผู้ป่วยฉุกเฉิน | M16: ฟิล์ม
A17: =TEXT(C17, "mmm") -> ก.ย. | B17: =TEXT(C17,"[$-41E]dddd") -> พุธ | C17: 46267 | D17: 69-15513 | E17: แล้วเสร็จ | F17: MEDCMU-020158 | G17: =INDEX('เครื่องมือแพทย์ (956)'!$C:$C,MATCH(F17,'เครื่องมือแพทย์ (956)'!$B:$B,0)) -> Vital Sign Monitors | H17: =INDEX('เครื่องมือแพทย์ (956)'!$E:$E,MATCH(F17,'เครื่องมือแพทย์ (956)'!$B:$B,0)) -> PHILIPS | I17: =INDEX('เครื่องมือแพทย์ (956)'!$F:$F,MATCH(F17,'เครื่องมือแพทย์ (956)'!$B:$B,0)) -> Early Vue VS30 | J17: =INDEX('เครื่องมือแพทย์ (956)'!$G:$G,MATCH(F17,'เครื่องมือแพทย์ (956)'!$B:$B,0)) -> DE75144935 | K17: =INDEX('เครื่องมือแพทย์ (956)'!$J:$J,MATCH(F17,'เครื่องมือแพทย์ (956)'!$B:$B,0)) -> ห้องตรวจเบอร์ 27 (ห้องตรวจพิเศษเด็ก 1) | L17: =INDEX('เครื่องมือแพทย์ (956)'!$K:$K,MATCH(F17,'เครื่องมือแพทย์ (956)'!$B:$B,0)) -> งานการพยาบาลผู้ป่วยนอกและผู้ป่วยฉุกเฉิน | M17: ฟิล์ม
A18: =TEXT(C18, "mmm") -> ก.ย. | B18: =TEXT(C18,"[$-41E]dddd") -> พุธ | C18: 46267 | D18: 69-15514 | E18: แล้วเสร็จ | F18: MEDCMU-010478 | G18: =INDEX('เครื่องมือแพทย์ (956)'!$C:$C,MATCH(F18,'เครื่องมือแพทย์ (956)'!$B:$B,0)) -> Pulse Oximeter | H18: =INDEX('เครื่องมือแพทย์ (956)'!$E:$E,MATCH(F18,'เครื่องมือแพทย์ (956)'!$B:$B,0)) -> Masimo | I18: =INDEX('เครื่องมือแพทย์ (956)'!$F:$F,MATCH(F18,'เครื่องมือแพทย์ (956)'!$B:$B,0)) -> Rad-5v | J18: =INDEX('เครื่องมือแพทย์ (956)'!$G:$G,MATCH(F18,'เครื่องมือแพทย์ (956)'!$B:$B,0)) -> N23600 | K18: =INDEX('เครื่องมือแพทย์ (956)'!$J:$J,MATCH(F18,'เครื่องมือแพทย์ (956)'!$B:$B,0)) -> ห้องตรวจเบอร์ 27 (ห้องตรวจพิเศษเด็ก 1) | L18: =INDEX('เครื่องมือแพทย์ (956)'!$K:$K,MATCH(F18,'เครื่องมือแพทย์ (956)'!$B:$B,0)) -> งานการพยาบาลผู้ป่วยนอกและผู้ป่วยฉุกเฉิน | M18: อั้ม
A19: =TEXT(C19, "mmm") -> ก.ย. | B19: =TEXT(C19,"[$-41E]dddd") -> พุธ | C19: 46267 | D19: 69-15515 | E19: แล้วเสร็จ | F19: MEDCMU-010477 | G19: =INDEX('เครื่องมือแพทย์ (956)'!$C:$C,MATCH(F19,'เครื่องมือแพทย์ (956)'!$B:$B,0)) -> Vital Sign Monitors | H19: =INDEX('เครื่องมือแพทย์ (956)'!$E:$E,MATCH(F19,'เครื่องมือแพทย์ (956)'!$B:$B,0)) -> Heal Force | I19: =INDEX('เครื่องมือแพทย์ (956)'!$F:$F,MATCH(F19,'เครื่องมือแพทย์ (956)'!$B:$B,0)) -> Classic-90 | J19: =INDEX('เครื่องมือแพทย์ (956)'!$G:$G,MATCH(F19,'เครื่องมือแพทย์ (956)'!$B:$B,0)) -> J2600PG00077 | K19: =INDEX('เครื่องมือแพทย์ (956)'!$J:$J,MATCH(F19,'เครื่องมือแพทย์ (956)'!$B:$B,0)) -> ห้องตรวจเบอร์ 27 (ห้องตรวจพิเศษเด็ก 1) | L19: =INDEX('เครื่องมือแพทย์ (956)'!$K:$K,MATCH(F19,'เครื่องมือแพทย์ (956)'!$B:$B,0)) -> งานการพยาบาลผู้ป่วยนอกและผู้ป่วยฉุกเฉิน | M19: อั้ม
... A49: =TEXT(C49, "mmm") -> ก.ย. | B49: =TEXT(C49,"[$-41E]dddd") -> พุธ | C49: 46267 | D49: 69-15553 | E49: แล้วเสร็จ | F49: MEDCMU-018977 | G49: =INDEX('เครื่องมือแพทย์ (956)'!$C:$C,MATCH(F49,'เครื่องมือแพทย์ (956)'!$B:$B,0)) -> Vital Sign Monitors | H49: =INDEX('เครื่องมือแพทย์ (956)'!$E:$E,MATCH(F49,'เครื่องมือแพทย์ (956)'!$B:$B,0)) -> Philips | I49: =INDEX('เครื่องมือแพทย์ (956)'!$F:$F,MATCH(F49,'เครื่องมือแพทย์ (956)'!$B:$B,0)) -> MX100 | J49: =INDEX('เครื่องมือแพทย์ (956)'!$G:$G,MATCH(F49,'เครื่องมือแพทย์ (956)'!$B:$B,0)) -> DE752M4953,KSA5351444 | K49: =INDEX('เครื่องมือแพทย์ (956)'!$J:$J,MATCH(F49,'เครื่องมือแพทย์ (956)'!$B:$B,0)) -> ฉุกเฉิน | L49: =INDEX('เครื่องมือแพทย์ (956)'!$K:$K,MATCH(F49,'เครื่องมือแพทย์ (956)'!$B:$B,0)) -> งานการพยาบาลผู้ป่วยนอกและผู้ป่วยฉุกเฉิน | M49: NH
A50: =TEXT(C50, "mmm") -> ก.ย. | B50: =TEXT(C50,"[$-41E]dddd") -> พุธ | C50: 46267 | D50: 69-15554 | E50: แล้วเสร็จ | F50: MEDCMU-020654 | G50: =INDEX('เครื่องมือแพทย์ (956)'!$C:$C,MATCH(F50,'เครื่องมือแพทย์ (956)'!$B:$B,0)) -> Electrocardiography | H50: =INDEX('เครื่องมือแพทย์ (956)'!$E:$E,MATCH(F50,'เครื่องมือแพทย์ (956)'!$B:$B,0)) -> Nihon Kohden | I50: =INDEX('เครื่องมือแพทย์ (956)'!$F:$F,MATCH(F50,'เครื่องมือแพทย์ (956)'!$B:$B,0)) -> ECG-3350 | J50: =INDEX('เครื่องมือแพทย์ (956)'!$G:$G,MATCH(F50,'เครื่องมือแพทย์ (956)'!$B:$B,0)) -> 0101204 | K50: =INDEX('เครื่องมือแพทย์ (956)'!$J:$J,MATCH(F50,'เครื่องมือแพทย์ (956)'!$B:$B,0)) -> หน่วยวิศวกรรมชีวการแพทย์ | L50: =INDEX('เครื่องมือแพทย์ (956)'!$K:$K,MATCH(F50,'เครื่องมือแพทย์ (956)'!$B:$B,0)) -> งานซ่อมบำรุง | M50: NH | N50: เครื่องอยู่ที่ ER
A51: =TEXT(C51, "mmm") -> ก.ย. | B51: =TEXT(C51,"[$-41E]dddd") -> พฤหัสบดี | C51: 46268 | D51: 69-15600 | E51: แล้วเสร็จ | F51: MEDCMU-002503 | G51: =INDEX('เครื่องมือแพทย์ (956)'!$C:$C,MATCH(F51,'เครื่องมือแพทย์ (956)'!$B:$B,0)) -> Vital Sign Monitors | H51: =INDEX('เครื่องมือแพทย์ (956)'!$E:$E,MATCH(F51,'เครื่องมือแพทย์ (956)'!$B:$B,0)) -> Edan | I51: =INDEX('เครื่องมือแพทย์ (956)'!$F:$F,MATCH(F51,'เครื่องมือแพทย์ (956)'!$B:$B,0)) -> M3A | J51: =INDEX('เครื่องมือแพทย์ (956)'!$G:$G,MATCH(F51,'เครื่องมือแพทย์ (956)'!$B:$B,0)) -> 261164-M17401090023-01 | K51: =INDEX('เครื่องมือแพทย์ (956)'!$J:$J,MATCH(F51,'เครื่องมือแพทย์ (956)'!$B:$B,0)) -> หอผู้ป่วยอายุรกรรมหญิง 2 | L51: =INDEX('เครื่องมือแพทย์ (956)'!$K:$K,MATCH(F51,'เครื่องมือแพทย์ (956)'!$B:$B,0)) -> งานการพยาบาลผู้ป่วยอายุรศาสตร์ | M51: ฝ้าย
A52: =TEXT(C52, "mmm") -> ก.ย. | B52: =TEXT(C52,"[$-41E]dddd") -> พฤหัสบดี | C52: 46268 | D52: 69-15597 | E52: แล้วเสร็จ | F52: MEDCMU-002504 | G52: =INDEX('เครื่องมือแพทย์ (956)'!$C:$C,MATCH(F52,'เครื่องมือแพทย์ (956)'!$B:$B,0)) -> Vital Sign Monitors | H52: =INDEX('เครื่องมือแพทย์ (956)'!$E:$E,MATCH(F52,'เครื่องมือแพทย์ (956)'!$B:$B,0)) -> Nihon Kohden | I52: =INDEX('เครื่องมือแพทย์ (956)'!$F:$F,MATCH(F52,'เครื่องมือแพทย์ (956)'!$B:$B,0)) -> SVM-7260 | J52: =INDEX('เครื่องมือแพทย์ (956)'!$G:$G,MATCH(F52,'เครื่องมือแพทย์ (956)'!$B:$B,0)) -> 00082 | K52: =INDEX('เครื่องมือแพทย์ (956)'!$J:$J,MATCH(F52,'เครื่องมือแพทย์ (956)'!$B:$B,0)) -> หอผู้ป่วยอายุรกรรมหญิง 2 | L52: =INDEX('เครื่องมือแพทย์ (956)'!$K:$K,MATCH(F52,'เครื่องมือแพทย์ (956)'!$B:$B,0)) -> งานการพยาบาลผู้ป่วยอายุรศาสตร์ | M52: ฝ้าย
A53: =TEXT(C53, "mmm") -> ก.ย. | B53: =TEXT(C53,"[$-41E]dddd") -> พฤหัสบดี | C53: 46268 | D53: 69-15598 | E53: แล้วเสร็จ | F53: MEDCMU-019460 | G53: =INDEX('เครื่องมือแพทย์ (956)'!$C:$C,MATCH(F53,'เครื่องมือแพทย์ (956)'!$B:$B,0)) -> Pulse Oximeter | H53: =INDEX('เครื่องมือแพทย์ (956)'!$E:$E,MATCH(F53,'เครื่องมือแพทย์ (956)'!$B:$B,0)) -> EDAN | I53: =INDEX('เครื่องมือแพทย์ (956)'!$F:$F,MATCH(F53,'เครื่องมือแพทย์ (956)'!$B:$B,0)) -> H100B | J53: =INDEX('เครื่องมือแพทย์ (956)'!$G:$G,MATCH(F53,'เครื่องมือแพทย์ (956)'!$B:$B,0)) -> 360101-M23507660016 | K53: =INDEX('เครื่องมือแพทย์ (956)'!$J:$J,MATCH(F53,'เครื่องมือแพทย์ (956)'!$B:$B,0)) -> หอผู้ป่วยอายุรกรรมหญิง 2 | L53: =INDEX('เครื่องมือแพทย์ (956)'!$K:$K,MATCH(F53,'เครื่องมือแพทย์ (956)'!$B:$B,0)) -> งานการพยาบาลผู้ป่วยอายุรศาสตร์ | M53: ฝ้าย
A54: =TEXT(C54, "mmm") -> ก.ย. | B54: =TEXT(C54,"[$-41E]dddd") -> พฤหัสบดี | C54: 46268 | D54: 69-15611 | E54: แล้วเสร็จ | F54: MEDCMU-018756 | G54: =INDEX('เครื่องมือแพทย์ (956)'!$C:$C,MATCH(F54,'เครื่องมือแพทย์ (956)'!$B:$B,0)) -> Vital Sign Monitors | H54: =INDEX('เครื่องมือแพทย์ (956)'!$E:$E,MATCH(F54,'เครื่องมือแพทย์ (956)'!$B:$B,0)) -> Creative Medical | I54: =INDEX('เครื่องมือแพทย์ (956)'!$F:$F,MATCH(F54,'เครื่องมือแพทย์ (956)'!$B:$B,0)) -> PC-900 | J54: =INDEX('เครื่องมือแพทย์ (956)'!$G:$G,MATCH(F54,'เครื่องมือแพทย์ (956)'!$B:$B,0)) -> J0100RJ03152 | K54: =INDEX('เครื่องมือแพทย์ (956)'!$J:$J,MATCH(F54,'เครื่องมือแพทย์ (956)'!$B:$B,0)) -> หอผู้ป่วยสังเกตอาการ | L54: =INDEX('เครื่องมือแพทย์ (956)'!$K:$K,MATCH(F54,'เครื่องมือแพทย์ (956)'!$B:$B,0)) -> งานการพยาบาลผู้ป่วยนอกและผู้ป่วยฉุกเฉิน | M54: น้ำ
A55: =TEXT(C55, "mmm") -> ก.ย. | B55: =TEXT(C55,"[$-41E]dddd") -> พฤหัสบดี | C55: 46268 | D55: 69-15596 | E55: แล้วเสร็จ | F55: MEDCMU-013855 | G55: =INDEX('เครื่องมือแพทย์ (956)'!$C:$C,MATCH(F55,'เครื่องมือแพทย์ (956)'!$B:$B,0)) -> Pulse Oximeter | H55: =INDEX('เครื่องมือแพทย์ (956)'!$E:$E,MATCH(F55,'เครื่องมือแพทย์ (956)'!$B:$B,0)) -> Masimo | I55: =INDEX('เครื่องมือแพทย์ (956)'!$F:$F,MATCH(F55,'เครื่องมือแพทย์ (956)'!$B:$B,0)) -> Rad-5v | J55: =INDEX('เครื่องมือแพทย์ (956)'!$G:$G,MATCH(F55,'เครื่องมือแพทย์ (956)'!$B:$B,0)) -> N23563 | K55: =INDEX('เครื่องมือแพทย์ (956)'!$J:$J,MATCH(F55,'เครื่องมือแพทย์ (956)'!$B:$B,0)) -> ห้องตรวจเบอร์ 1(ห้องตรวจศัลยกรรม 1) | L55: =INDEX('เครื่องมือแพทย์ (956)'!$K:$K,MATCH(F55,'เครื่องมือแพทย์ (956)'!$B:$B,0)) -> งานการพยาบาลผู้ป่วยนอกและผู้ป่วยฉุกเฉิน | M55: ฟิล์ม
A56: =TEXT(C56, "mmm") -> ก.ย. | B56: =TEXT(C56,"[$-41E]dddd") -> พฤหัสบดี | C56: 46268 | D56: 69-15609 | E56: แล้วเสร็จ | F56: MEDCMU-020162 | G56: =INDEX('เครื่องมือแพทย์ (956)'!$C:$C,MATCH(F56,'เครื่องมือแพทย์ (956)'!$B:$B,0)) -> Pulse Oximeter | H56: =INDEX('เครื่องมือแพทย์ (956)'!$E:$E,MATCH(F56,'เครื่องมือแพทย์ (956)'!$B:$B,0)) -> ChoiceMed | I56: =INDEX('เครื่องมือแพทย์ (956)'!$F:$F,MATCH(F56,'เครื่องมือแพทย์ (956)'!$B:$B,0)) -> MD300C29 | J56: =INDEX('เครื่องมือแพทย์ (956)'!$G:$G,MATCH(F56,'เครื่องมือแพทย์ (956)'!$B:$B,0)) -> 151312800774 | K56: =INDEX('เครื่องมือแพทย์ (956)'!$J:$J,MATCH(F56,'เครื่องมือแพทย์ (956)'!$B:$B,0)) -> งานทันตกรรม | L56: =INDEX('เครื่องมือแพทย์ (956)'!$K:$K,MATCH(F56,'เครื่องมือแพทย์ (956)'!$B:$B,0)) -> งานทันตกรรม | M56: ฟิล์ม
A57: =TEXT(C57, "mmm") -> ก.ย. | B57: =TEXT(C57,"[$-41E]dddd") -> พฤหัสบดี | C57: 46268 | D57: 69-15644 | E57: แล้วเสร็จ | F57: MEDCMU-010973 | G57: =INDEX('เครื่องมือแพทย์ (956)'!$C:$C,MATCH(F57,'เครื่องมือแพทย์ (956)'!$B:$B,0)) -> Electrosurgical Unit | H57: =INDEX('เครื่องมือแพทย์ (956)'!$E:$E,MATCH(F57,'เครื่องมือแพทย์ (956)'!$B:$B,0)) -> Cacteon | I57: =INDEX('เครื่องมือแพทย์ (956)'!$F:$F,MATCH(F57,'เครื่องมือแพทย์ (956)'!$B:$B,0)) -> Servotome | J57: =INDEX('เครื่องมือแพทย์ (956)'!$G:$G,MATCH(F57,'เครื่องมือแพทย์ (956)'!$B:$B,0)) -> 878717009 | K57: =INDEX('เครื่องมือแพทย์ (956)'!$J:$J,MATCH(F57,'เครื่องมือแพทย์ (956)'!$B:$B,0)) -> งานทันตกรรม | L57: =INDEX('เครื่องมือแพทย์ (956)'!$K:$K,MATCH(F57,'เครื่องมือแพทย์ (956)'!$B:$B,0)) -> งานทันตกรรม | M57: ฟิล์ม
A58: =TEXT(C58, "mmm") -> ก.ย. | B58: =TEXT(C58,"[$-41E]dddd") -> พฤหัสบดี | C58: 46268 | D58: 69-15640 | E58: แล้วเสร็จ | F58: MEDCMU-009178 | G58: =INDEX('เครื่องมือแพทย์ (956)'!$C:$C,MATCH(F58,'เครื่องมือแพทย์ (956)'!$B:$B,0)) -> Pulse Oximeter | H58: =INDEX('เครื่องมือแพทย์ (956)'!$E:$E,MATCH(F58,'เครื่องมือแพทย์ (956)'!$B:$B,0)) -> Mindray | I58: =INDEX('เครื่องมือแพทย์ (956)'!$F:$F,MATCH(F58,'เครื่องมือแพทย์ (956)'!$B:$B,0)) -> PM-60 | J58: =INDEX('เครื่องมือแพทย์ (956)'!$G:$G,MATCH(F58,'เครื่องมือแพทย์ (956)'!$B:$B,0)) -> CR-95204190 | K58: =INDEX('เครื่องมือแพทย์ (956)'!$J:$J,MATCH(F58,'เครื่องมือแพทย์ (956)'!$B:$B,0)) -> หอผู้ป่วยศัลยกรรมหญิง 3 | L58: =INDEX('เครื่องมือแพทย์ (956)'!$K:$K,MATCH(F58,'เครื่องมือแพทย์ (956)'!$B:$B,0)) -> งานการพยาบาลผู้ป่วยศัลยศาสตร์ | M58: น้ำ
A59: =TEXT(C59, "mmm") -> ก.ย. | B59: =TEXT(C59,"[$-41E]dddd") -> พฤหัสบดี | C59: 46268 | D59: 69-15604 | E59: แล้วเสร็จ | F59: MEDCMU-009198 | G59: =INDEX('เครื่องมือแพทย์ (956)'!$C:$C,MATCH(F59,'เครื่องมือแพทย์ (956)'!$B:$B,0)) -> Vital Sign Monitors | H59: =INDEX('เครื่องมือแพทย์ (956)'!$E:$E,MATCH(F59,'เครื่องมือแพทย์ (956)'!$B:$B,0)) -> Edan | I59: =INDEX('เครื่องมือแพทย์ (956)'!$F:$F,MATCH(F59,'เครื่องมือแพทย์ (956)'!$B:$B,0)) -> M3A | J59: =INDEX('เครื่องมือแพทย์ (956)'!$G:$G,MATCH(F59,'เครื่องมือแพทย์ (956)'!$B:$B,0)) -> 261064-M16C04630015-01 | K59: =INDEX('เครื่องมือแพทย์ (956)'!$J:$J,MATCH(F59,'เครื่องมือแพทย์ (956)'!$B:$B,0)) -> หอผู้ป่วยศัลยกรรมหญิง 3 | L59: =INDEX('เครื่องมือแพทย์ (956)'!$K:$K,MATCH(F59,'เครื่องมือแพทย์ (956)'!$B:$B,0)) -> งานการพยาบาลผู้ป่วยศัลยศาสตร์ | M59: น้ำ
A60: =TEXT(C60, "mmm") -> ก.ย. | B60: =TEXT(C60,"[$-41E]dddd") -> พฤหัสบดี | C60: 46268 | D60: 69-15639 | E60: แล้วเสร็จ | F60: MEDCMU-009199 | G60: =INDEX('เครื่องมือแพทย์ (956)'!$C:$C,MATCH(F60,'เครื่องมือแพทย์ (956)'!$B:$B,0)) -> Vital Sign Monitors | H60: =INDEX('เครื่องมือแพทย์ (956)'!$E:$E,MATCH(F60,'เครื่องมือแพทย์ (956)'!$B:$B,0)) -> Edan | I60: =INDEX('เครื่องมือแพทย์ (956)'!$F:$F,MATCH(F60,'เครื่องมือแพทย์ (956)'!$B:$B,0)) -> M3A | J60: =INDEX('เครื่องมือแพทย์ (956)'!$G:$G,MATCH(F60,'เครื่องมือแพทย์ (956)'!$B:$B,0)) -> 261164-M17401090029-01 | K60: =INDEX('เครื่องมือแพทย์ (956)'!$J:$J,MATCH(F60,'เครื่องมือแพทย์ (956)'!$B:$B,0)) -> หอผู้ป่วยศัลยกรรมหญิง 3 | L60: =INDEX('เครื่องมือแพทย์ (956)'!$K:$K,MATCH(F60,'เครื่องมือแพทย์ (956)'!$B:$B,0)) -> งานการพยาบาลผู้ป่วยศัลยศาสตร์ | M60: น้ำ
A61: =TEXT(C61, "mmm") -> ก.ย. | B61: =TEXT(C61,"[$-41E]dddd") -> พฤหัสบดี | C61: 46268 | D61: 69-15603 | E61: แล้วเสร็จ | F61: MEDCMU-010142 | G61: =INDEX('เครื่องมือแพทย์ (956)'!$C:$C,MATCH(F61,'เครื่องมือแพทย์ (956)'!$B:$B,0)) -> Pulse Oximeter | H61: =INDEX('เครื่องมือแพทย์ (956)'!$E:$E,MATCH(F61,'เครื่องมือแพทย์ (956)'!$B:$B,0)) -> Masimo | I61: =INDEX('เครื่องมือแพทย์ (956)'!$F:$F,MATCH(F61,'เครื่องมือแพทย์ (956)'!$B:$B,0)) -> Rad-5v | J61: =INDEX('เครื่องมือแพทย์ (956)'!$G:$G,MATCH(F61,'เครื่องมือแพทย์ (956)'!$B:$B,0)) -> N23592 | K61: =INDEX('เครื่องมือแพทย์ (956)'!$J:$J,MATCH(F61,'เครื่องมือแพทย์ (956)'!$B:$B,0)) -> ศูนย์สุขภาพมหาวิทยาลัยเชียงใหม่ | L61: =INDEX('เครื่องมือแพทย์ (956)'!$K:$K,MATCH(F61,'เครื่องมือแพทย์ (956)'!$B:$B,0)) -> งานการพยาบาลผู้ป่วยนอกและผู้ป่วยฉุกเฉิน | M61: ฟิล์ม
A62: =TEXT(C62, "mmm") -> ก.ย. | B62: =TEXT(C62,"[$-41E]dddd") -> พฤหัสบดี | C62: 46268 | D62: 69-15610 | E62: แล้วเสร็จ | F62: MEDCMU-010056 | G62: =INDEX('เครื่องมือแพทย์ (956)'!$C:$C,MATCH(F62,'เครื่องมือแพทย์ (956)'!$B:$B,0)) -> Pulse Oximeter | H62: =INDEX('เครื่องมือแพทย์ (956)'!$E:$E,MATCH(F62,'เครื่องมือแพทย์ (956)'!$B:$B,0)) -> Masimo | I62: =INDEX('เครื่องมือแพทย์ (956)'!$F:$F,MATCH(F62,'เครื่องมือแพทย์ (956)'!$B:$B,0)) -> Rad-5v | J62: =INDEX('เครื่องมือแพทย์ (956)'!$G:$G,MATCH(F62,'เครื่องมือแพทย์ (956)'!$B:$B,0)) -> N29730 | K62: =INDEX('เครื่องมือแพทย์ (956)'!$J:$J,MATCH(F62,'เครื่องมือแพทย์ (956)'!$B:$B,0)) -> ห้องตรวจเบอร์ 23 (ห้องตรวจพิเศษอายุรกรรม 3) | L62: =INDEX('เครื่องมือแพทย์ (956)'!$K:$K,MATCH(F62,'เครื่องมือแพทย์ (956)'!$B:$B,0)) -> งานการพยาบาลผู้ป่วยนอกและผู้ป่วยฉุกเฉิน | M62: ฟิล์ม
... A64: =TEXT(C64, "mmm") -> ก.ย. | B64: =TEXT(C64,"[$-41E]dddd") -> พฤหัสบดี | C64: 46268 | D64: 69-15606 | E64: แล้วเสร็จ | F64: MEDCMU-019529 | G64: =INDEX('เครื่องมือแพทย์ (956)'!$C:$C,MATCH(F64,'เครื่องมือแพทย์ (956)'!$B:$B,0)) -> Vital Sign Monitors | H64: =INDEX('เครื่องมือแพทย์ (956)'!$E:$E,MATCH(F64,'เครื่องมือแพทย์ (956)'!$B:$B,0)) -> Mindray | I64: =INDEX('เครื่องมือแพทย์ (956)'!$F:$F,MATCH(F64,'เครื่องมือแพทย์ (956)'!$B:$B,0)) -> VS-600 | J64: =INDEX('เครื่องมือแพทย์ (956)'!$G:$G,MATCH(F64,'เครื่องมือแพทย์ (956)'!$B:$B,0)) -> FU-32035196 | K64: =INDEX('เครื่องมือแพทย์ (956)'!$J:$J,MATCH(F64,'เครื่องมือแพทย์ (956)'!$B:$B,0)) -> ห้องตรวจเบอร์ 22 (ห้องตรวจอายุรกรรม 2) | L64: =INDEX('เครื่องมือแพทย์ (956)'!$K:$K,MATCH(F64,'เครื่องมือแพทย์ (956)'!$B:$B,0)) -> งานการพยาบาลผู้ป่วยนอกและผู้ป่วยฉุกเฉิน | M64: ฟิล์ม
A65: =TEXT(C65, "mmm") -> ก.ย. | B65: =TEXT(C65,"[$-41E]dddd") -> พฤหัสบดี | C65: 46268 | D65: 69-15612 | E65: แล้วเสร็จ | F65: MEDCMU-018396 | G65: =INDEX('เครื่องมือแพทย์ (956)'!$C:$C,MATCH(F65,'เครื่องมือแพทย์ (956)'!$B:$B,0)) -> Pulse Oximeter | H65: =INDEX('เครื่องมือแพทย์ (956)'!$E:$E,MATCH(F65,'เครื่องมือแพทย์ (956)'!$B:$B,0)) -> Bionics | I65: =INDEX('เครื่องมือแพทย์ (956)'!$F:$F,MATCH(F65,'เครื่องมือแพทย์ (956)'!$B:$B,0)) -> PalmCare plus | J65: =INDEX('เครื่องมือแพทย์ (956)'!$G:$G,MATCH(F65,'เครื่องมือแพทย์ (956)'!$B:$B,0)) -> 161-RH5231 | K65: =INDEX('เครื่องมือแพทย์ (956)'!$J:$J,MATCH(F65,'เครื่องมือแพทย์ (956)'!$B:$B,0)) -> OPD โรคจอตาและวุ้นตา | L65: =INDEX('เครื่องมือแพทย์ (956)'!$K:$K,MATCH(F65,'เครื่องมือแพทย์ (956)'!$B:$B,0)) -> ภาควิชาจักษุวิทยา | M65: ฟิล์ม | N65: 35903 คุณจสิยา
A66: =TEXT(C66, "mmm") -> ก.ย. | B66: =TEXT(C66,"[$-41E]dddd") -> พฤหัสบดี | C66: 46268 | D66: 69-15595 | E66: แล้วเสร็จ | F66: MEDCMU-000388 | G66: =INDEX('เครื่องมือแพทย์ (956)'!$C:$C,MATCH(F66,'เครื่องมือแพทย์ (956)'!$B:$B,0)) -> Vital Sign Monitors | H66: =INDEX('เครื่องมือแพทย์ (956)'!$E:$E,MATCH(F66,'เครื่องมือแพทย์ (956)'!$B:$B,0)) -> Edan | I66: =INDEX('เครื่องมือแพทย์ (956)'!$F:$F,MATCH(F66,'เครื่องมือแพทย์ (956)'!$B:$B,0)) -> iM20 | J66: =INDEX('เครื่องมือแพทย์ (956)'!$G:$G,MATCH(F66,'เครื่องมือแพทย์ (956)'!$B:$B,0)) -> 260374-M19205210002 | K66: =INDEX('เครื่องมือแพทย์ (956)'!$J:$J,MATCH(F66,'เครื่องมือแพทย์ (956)'!$B:$B,0)) -> หน่วยตรวจสวนหัวใจและหลอดเลือด | L66: =INDEX('เครื่องมือแพทย์ (956)'!$K:$K,MATCH(F66,'เครื่องมือแพทย์ (956)'!$B:$B,0)) -> งานการพยาบาลผู้ป่วยอายุรศาสตร์ | M66: ฟิล์ม
A67: =TEXT(C67, "mmm") -> ก.ย. | B67: =TEXT(C67,"[$-41E]dddd") -> พฤหัสบดี | C67: 46268 | D67: 69-15599 | E67: แล้วเสร็จ | F67: MEDCMU-000406 | G67: =INDEX('เครื่องมือแพทย์ (956)'!$C:$C,MATCH(F67,'เครื่องมือแพทย์ (956)'!$B:$B,0)) -> Vital Sign Monitors | H67: =INDEX('เครื่องมือแพทย์ (956)'!$E:$E,MATCH(F67,'เครื่องมือแพทย์ (956)'!$B:$B,0)) -> Philips | I67: =INDEX('เครื่องมือแพทย์ (956)'!$F:$F,MATCH(F67,'เครื่องมือแพทย์ (956)'!$B:$B,0)) -> SureSigns VM4 | J67: =INDEX('เครื่องมือแพทย์ (956)'!$G:$G,MATCH(F67,'เครื่องมือแพทย์ (956)'!$B:$B,0)) -> US90328532 | K67: =INDEX('เครื่องมือแพทย์ (956)'!$J:$J,MATCH(F67,'เครื่องมือแพทย์ (956)'!$B:$B,0)) -> หน่วยตรวจสวนหัวใจและหลอดเลือด | L67: =INDEX('เครื่องมือแพทย์ (956)'!$K:$K,MATCH(F67,'เครื่องมือแพทย์ (956)'!$B:$B,0)) -> งานการพยาบาลผู้ป่วยอายุรศาสตร์ | M67: ฟิล์ม
A68: =TEXT(C68, "mmm") -> ก.ย. | B68: =TEXT(C68,"[$-41E]dddd") -> พฤหัสบดี | C68: 46268 | D68: 69-15667 | E68: แล้วเสร็จ | F68: MEDCMU-000403 | G68: =INDEX('เครื่องมือแพทย์ (956)'!$C:$C,MATCH(F68,'เครื่องมือแพทย์ (956)'!$B:$B,0)) -> Electrosurgical Unit | H68: =INDEX('เครื่องมือแพทย์ (956)'!$E:$E,MATCH(F68,'เครื่องมือแพทย์ (956)'!$B:$B,0)) -> Erbe | I68: =INDEX('เครื่องมือแพทย์ (956)'!$F:$F,MATCH(F68,'เครื่องมือแพทย์ (956)'!$B:$B,0)) -> Vio 100 C | J68: =INDEX('เครื่องมือแพทย์ (956)'!$G:$G,MATCH(F68,'เครื่องมือแพทย์ (956)'!$B:$B,0)) -> 11309574 | K68: =INDEX('เครื่องมือแพทย์ (956)'!$J:$J,MATCH(F68,'เครื่องมือแพทย์ (956)'!$B:$B,0)) -> หน่วยตรวจสวนหัวใจและหลอดเลือด | L68: =INDEX('เครื่องมือแพทย์ (956)'!$K:$K,MATCH(F68,'เครื่องมือแพทย์ (956)'!$B:$B,0)) -> งานการพยาบาลผู้ป่วยอายุรศาสตร์ | M68: ฟิล์ม
A69: =TEXT(C69, "mmm") -> ก.ย. | B69: =TEXT(C69,"[$-41E]dddd") -> พฤหัสบดี | C69: 46268 | D69: 69-15642 | E69: แล้วเสร็จ | F69: MEDCMU-010278 | G69: =INDEX('เครื่องมือแพทย์ (956)'!$C:$C,MATCH(F69,'เครื่องมือแพทย์ (956)'!$B:$B,0)) -> Vital Sign Monitors | H69: =INDEX('เครื่องมือแพทย์ (956)'!$E:$E,MATCH(F69,'เครื่องมือแพทย์ (956)'!$B:$B,0)) -> Philips | I69: =INDEX('เครื่องมือแพทย์ (956)'!$F:$F,MATCH(F69,'เครื่องมือแพทย์ (956)'!$B:$B,0)) -> IntelliVue MP50 | J69: =INDEX('เครื่องมือแพทย์ (956)'!$G:$G,MATCH(F69,'เครื่องมือแพทย์ (956)'!$B:$B,0)) -> DE862116 | K69: =INDEX('เครื่องมือแพทย์ (956)'!$J:$J,MATCH(F69,'เครื่องมือแพทย์ (956)'!$B:$B,0)) -> หอผู้ป่วยหนักกุมารเวชกรรม | L69: =INDEX('เครื่องมือแพทย์ (956)'!$K:$K,MATCH(F69,'เครื่องมือแพทย์ (956)'!$B:$B,0)) -> งานการพยาบาลผู้ป่วยกุมารเวชศาสตร์ | M69: ฟิล์ม | N69: ENT2 เป็นคนส่ง
A70: =TEXT(C70, "mmm") -> ก.ย. | B70: =TEXT(C70,"[$-41E]dddd") -> พฤหัสบดี | C70: 46268 | D70: 69-15607 | E70: แล้วเสร็จ | F70: MEDCMU-002455 | G70: =INDEX('เครื่องมือแพทย์ (956)'!$C:$C,MATCH(F70,'เครื่องมือแพทย์ (956)'!$B:$B,0)) -> Vital Sign Monitors | H70: =INDEX('เครื่องมือแพทย์ (956)'!$E:$E,MATCH(F70,'เครื่องมือแพทย์ (956)'!$B:$B,0)) -> Philips | I70: =INDEX('เครื่องมือแพทย์ (956)'!$F:$F,MATCH(F70,'เครื่องมือแพทย์ (956)'!$B:$B,0)) -> Efficia CM10 | J70: =INDEX('เครื่องมือแพทย์ (956)'!$G:$G,MATCH(F70,'เครื่องมือแพทย์ (956)'!$B:$B,0)) -> CN92383267 | K70: =INDEX('เครื่องมือแพทย์ (956)'!$J:$J,MATCH(F70,'เครื่องมือแพทย์ (956)'!$B:$B,0)) -> หอผู้ป่วยอายุรกรรมชาย 3 | L70: =INDEX('เครื่องมือแพทย์ (956)'!$K:$K,MATCH(F70,'เครื่องมือแพทย์ (956)'!$B:$B,0)) -> งานการพยาบาลผู้ป่วยอายุรศาสตร์ | M70: น้ำ
...

Sheet เครื่องมือแพทย์ (956)
A1: ลำดับ | B1: รหัสเครื่อง | C1: ชื่อเครื่อง | D1: ชื่อเครื่องภาษาไทย | E1: ยี่ห้อ | F1: รุ่น | G1: SerialNo | H1: เลขครุภัณฑ์ | I1: ชื่อหน่วยงานเจ้าของเครื่อง | J1: ชื่อหน่วยงานที่ใช้เครื่อง | K1: งาน | L1: จองคิว | M1: หมายเหตุ | N1: STATUS (NH) | O1: DATE | P1: หมายเหตุ N Health | Q1: เปลี่ยน AC Plug | R1: Battery เสื่อม | S1: Battery Bios เสื่อม
A2: 1 | B2: MEDCMU-000022 | C2: Vital Sign Monitors | D2: เครื่องติดตามการทำงานของหัวใจและสัญญาณชีพ | E2: Philips | F2: Efficia CM10 | G2: CN62637717 | H2: DF(1)09-6515-026-0023/62(6) | I2: หอผู้ป่วยปลูกถ่ายไขกระดูกและให้เคมีบำบัดขนาดสูง | J2: หอผู้ป่วยปลูกถ่ายไขกระดูกและให้เคมีบำบัดขนาดสูง | K2: งานการพยาบาลผู้ป่วยอายุรศาสตร์ | L2: =INDEX(จองคิว!$C:$C,MATCH('เครื่องมือแพทย์ (956)'!B2,จองคิว!$F:$F,0)) -> 46268 | N2: PASS | O2: 46268 | P2: ไม่มี EKG,SpO2 มาให้ใช้ของเครื่องอื่นในการสอบเทียบ , ผ้า Cuff มีลมรั่ว
A3: 2 | B3: MEDCMU-000040 | C3: Electrocardiography | D3: เครื่องตรวจวิเคราะห์คลื่นไฟฟ้าหัวใจ | E3: Philips | F3: PageWriter TC10 | G3: CNN1810996 | H3: DF(1)09-6545-018-0262/62(1) | I3: หอผู้ป่วยปลูกถ่ายไขกระดูกและให้เคมีบำบัดขนาดสูง | J3: หอผู้ป่วยปลูกถ่ายไขกระดูกและให้เคมีบำบัดขนาดสูง | K3: งานการพยาบาลผู้ป่วยอายุรศาสตร์ | L3: =INDEX(จองคิว!$C:$C,MATCH('เครื่องมือแพทย์ (956)'!B3,จองคิว!$F:$F,0)) -> 46268 | N3: PASS | O3: 46268 | P3: Battery เสื่อมสภาพ | R3: /
A4: 3 | B4: MEDCMU-000046 | C4: Vital Sign Monitors | D4: เครื่องติดตามการทำงานของหัวใจและสัญญาณชีพ | E4: Philips | F4: Efficia CM10 | G4: CN62637715 | H4: DF(1)09-6515-026-0023/62(3) | I4: หอผู้ป่วยปลูกถ่ายไขกระดูกและให้เคมีบำบัดขนาดสูง | J4: หอผู้ป่วยปลูกถ่ายไขกระดูกและให้เคมีบำบัดขนาดสูง | K4: งานการพยาบาลผู้ป่วยอายุรศาสตร์ | L4: =INDEX(จองคิว!$C:$C,MATCH('เครื่องมือแพทย์ (956)'!B4,จองคิว!$F:$F,0)) -> 46268 | N4: PASS | O4: 46268
A5: 4 | B5: MEDCMU-000049 | C5: Vital Sign Monitors | D5: เครื่องติดตามการทำงานของหัวใจและสัญญาณชีพ | E5: Philips | F5: Efficia CM10 | G5: CN62637713 | H5: DF(1)09-6515-026-0023/62(5) | I5: หอผู้ป่วยปลูกถ่ายไขกระดูกและให้เคมีบำบัดขนาดสูง | J5: หอผู้ป่วยปลูกถ่ายไขกระดูกและให้เคมีบำบัดขนาดสูง | K5: งานการพยาบาลผู้ป่วยอายุรศาสตร์ | L5: =INDEX(จองคิว!$C:$C,MATCH('เครื่องมือแพทย์ (956)'!B5,จองคิว!$F:$F,0)) -> 46268 | N5: PASS | O5: 46268
A6: 5 | B6: MEDCMU-000055 | C6: Vital Sign Monitors | D6: เครื่องติดตามการทำงานของหัวใจและสัญญาณชีพ | E6: Bionet | F6: BM5 | G6: D8O040021 | H6: HI920209-6515-026-0003/56(18) | I6: หอผู้ป่วยปลูกถ่ายไขกระดูกและให้เคมีบำบัดขนาดสูง | J6: หอผู้ป่วยปลูกถ่ายไขกระดูกและให้เคมีบำบัดขนาดสูง | K6: งานการพยาบาลผู้ป่วยอายุรศาสตร์ | L6: =INDEX(จองคิว!$C:$C,MATCH('เครื่องมือแพทย์ (956)'!B6,จองคิว!$F:$F,0)) -> 46268 | N6: PASS | O6: 46268 | P6: ฉนวนหุ้มสาย EKG เสื่อมสภาพ , Battery เสื่อมสภาพ | R6: /
A7: 6 | B7: MEDCMU-000057 | C7: Vital Sign Monitors | D7: เครื่องติดตามการทำงานของหัวใจและสัญญาณชีพ | E7: Philips | F7: Efficia CM10 | G7: CN62635735 | H7: DF(1)09-6515-026-0023/62(7) | I7: หอผู้ป่วยปลูกถ่ายไขกระดูกและให้เคมีบำบัดขนาดสูง | J7: หอผู้ป่วยปลูกถ่ายไขกระดูกและให้เคมีบำบัดขนาดสูง | K7: งานการพยาบาลผู้ป่วยอายุรศาสตร์ | L7: =INDEX(จองคิว!$C:$C,MATCH('เครื่องมือแพทย์ (956)'!B7,จองคิว!$F:$F,0)) -> 46268 | N7: PASS | O7: 46268
A8: 7 | B8: MEDCMU-000070 | C8: Vital Sign Monitors | D8: เครื่องติดตามการทำงานของหัวใจและสัญญาณชีพ | E8: Bionet | F8: BM5 | G8: D8O0600071 | H8: HI920209-6515-026-0003/57(8) | I8: หอผู้ป่วยปลูกถ่ายไขกระดูกและให้เคมีบำบัดขนาดสูง | J8: หอผู้ป่วยปลูกถ่ายไขกระดูกและให้เคมีบำบัดขนาดสูง | K8: งานการพยาบาลผู้ป่วยอายุรศาสตร์ | L8: =INDEX(จองคิว!$C:$C,MATCH('เครื่องมือแพทย์ (956)'!B8,จองคิว!$F:$F,0)) -> 46268 | N8: PASS | O8: 46268
A9: 8 | B9: MEDCMU-000076 | C9: Vital Sign Monitors | D9: เครื่องติดตามการทำงานของหัวใจและสัญญาณชีพ | E9: Philips | F9: Efficia CM10 | G9: CN62637716 | H9: DF(1)09-6515-026-0023/62(2) | I9: หอผู้ป่วยปลูกถ่ายไขกระดูกและให้เคมีบำบัดขนาดสูง | J9: หอผู้ป่วยปลูกถ่ายไขกระดูกและให้เคมีบำบัดขนาดสูง | K9: งานการพยาบาลผู้ป่วยอายุรศาสตร์ | L9: =INDEX(จองคิว!$C:$C,MATCH('เครื่องมือแพทย์ (956)'!B9,จองคิว!$F:$F,0)) -> 46268 | N9: PASS | O9: 46268
A10: 9 | B10: MEDCMU-000082 | C10: Vital Sign Monitors | D10: เครื่องติดตามการทำงานของหัวใจและสัญญาณชีพ | E10: Philips | F10: Efficia CM10 | G10: CN62637714 | H10: DF(1)09-6515-026-0023/62(4) | I10: หอผู้ป่วยปลูกถ่ายไขกระดูกและให้เคมีบำบัดขนาดสูง | J10: หอผู้ป่วยปลูกถ่ายไขกระดูกและให้เคมีบำบัดขนาดสูง | K10: งานการพยาบาลผู้ป่วยอายุรศาสตร์ | L10: =INDEX(จองคิว!$C:$C,MATCH('เครื่องมือแพทย์ (956)'!B10,จองคิว!$F:$F,0)) -> 46268 | N10: PASS | O10: 46268
A11: 10 | B11: MEDCMU-000101 | C11: Vital Sign Monitors | D11: เครื่องติดตามการทำงานของหัวใจและสัญญาณชีพ | E11: Philips | F11: Efficia CM100 | G11: CN62626250 | H11: DF0409-6545-018-0211/59(5) | I11: หน่วยเปลี่ยนไตและไตเทียม | J11: หน่วยเปลี่ยนไตและไตเทียม | K11: งานการพยาบาลผู้ป่วยอายุรศาสตร์ | L11: =INDEX(จองคิว!$C:$C,MATCH('เครื่องมือแพทย์ (956)'!B11,จองคิว!$F:$F,0)) -> 46288 | N11: PASS | O11: 46288
A12: 11 | B12: MEDCMU-000102 | C12: Vital Sign Monitors | D12: เครื่องติดตามการทำงานของหัวใจและสัญญาณชีพ | E12: Philips | F12: Efficia CM100 | G12: CN62626316 | H12: DF0409-6545-018-0211/59(7) | I12: หน่วยเปลี่ยนไตและไตเทียม | J12: หน่วยเปลี่ยนไตและไตเทียม | K12: งานการพยาบาลผู้ป่วยอายุรศาสตร์ | L12: =INDEX(จองคิว!$C:$C,MATCH('เครื่องมือแพทย์ (956)'!B12,จองคิว!$F:$F,0)) -> 46288 | N12: PASS | O12: 46288
A13: 12 | B13: MEDCMU-000103 | C13: Vital Sign Monitors | D13: เครื่องติดตามการทำงานของหัวใจและสัญญาณชีพ | E13: Philips | F13: Efficia CM100 | G13: CN62626241 | H13: DF0409-6545-018-0211/59(6) | I13: หน่วยเปลี่ยนไตและไตเทียม | J13: หน่วยเปลี่ยนไตและไตเทียม | K13: งานการพยาบาลผู้ป่วยอายุรศาสตร์ | L13: =INDEX(จองคิว!$C:$C,MATCH('เครื่องมือแพทย์ (956)'!B13,จองคิว!$F:$F,0)) -> 46288 | N13: PASS | O13: 46288
A14: 13 | B14: MEDCMU-000203 | C14: Electrocardiography | D14: เครื่องตรวจวิเคราะห์คลื่นไฟฟ้าหัวใจ | E14: Fukuda Denshi | F14: Cardimax FX-7102 | G14: 50002158 | H14: HI920209-6530-008-0009/54(1) | I14: หน่วยไตเทียมฉุกเฉิน | J14: หน่วยไตเทียมฉุกเฉิน | K14: งานการพยาบาลผู้ป่วยอายุรศาสตร์ | L14: =INDEX(จองคิว!$C:$C,MATCH('เครื่องมือแพทย์ (956)'!B14,จองคิว!$F:$F,0)) -> 46286 | N14: PASS | O14: 46286 | P14: Battery เสื่อมสภาพ | R14: /
A15: 14 | B15: MEDCMU-000244 | C15: Vital Sign Monitors | D15: เครื่องติดตามการทำงานของหัวใจและสัญญาณชีพ | E15: Philips | F15: Efficia CM100 | G15: CN62626223 | H15: DF0409-6545-018-0211/59(3) | I15: หน่วยไตเทียมฉุกเฉิน | J15: หน่วยไตเทียมฉุกเฉิน | K15: งานการพยาบาลผู้ป่วยอายุรศาสตร์ | L15: =INDEX(จองคิว!$C:$C,MATCH('เครื่องมือแพทย์ (956)'!B15,จองคิว!$F:$F,0)) -> 46286 | N15: PASS | O15: 46286
A16: 15 | B16: MEDCMU-000245 | C16: Vital Sign Monitors | D16: เครื่องติดตามการทำงานของหัวใจและสัญญาณชีพ | E16: Philips | F16: Efficia CM100 | G16: CN62626227 | H16: DF0409-6545-018-0211/59(2) | I16: หน่วยไตเทียมฉุกเฉิน | J16: หน่วยไตเทียมฉุกเฉิน | K16: งานการพยาบาลผู้ป่วยอายุรศาสตร์ | L16: =INDEX(จองคิว!$C:$C,MATCH('เครื่องมือแพทย์ (956)'!B16,จองคิว!$F:$F,0)) -> 46286 | N16: PASS | O16: 46286
A17: 16 | B17: MEDCMU-000246 | C17: Vital Sign Monitors | D17: เครื่องติดตามการทำงานของหัวใจและสัญญาณชีพ | E17: Philips | F17: Efficia CM100 | G17: CN62626246 | H17: DF0409-6545-018-0211/59(4) | I17: หน่วยไตเทียมฉุกเฉิน | J17: หน่วยไตเทียมฉุกเฉิน | K17: งานการพยาบาลผู้ป่วยอายุรศาสตร์ | L17: =INDEX(จองคิว!$C:$C,MATCH('เครื่องมือแพทย์ (956)'!B17,จองคิว!$F:$F,0)) -> 46286 | N17: PASS | O17: 46286
A18: 17 | B18: MEDCMU-000247 | C18: Vital Sign Monitors | D18: เครื่องติดตามการทำงานของหัวใจและสัญญาณชีพ | E18: Philips | F18: SureSigns VM4 | G18: US12558612 | H18: HI920209-6695-019-0057/55(16) | I18: หน่วยไตเทียมฉุกเฉิน | J18: หน่วยไตเทียมฉุกเฉิน | K18: งานการพยาบาลผู้ป่วยอายุรศาสตร์ | L18: =INDEX(จองคิว!$C:$C,MATCH('เครื่องมือแพทย์ (956)'!B18,จองคิว!$F:$F,0)) -> 46286 | N18: PASS | O18: 46286 | P18: Battery เสื่อมสภาพ
A19: 18 | B19: MEDCMU-000281 | C19: Vital Sign Monitors | D19: เครื่องติดตามการทำงานของหัวใจและสัญญาณชีพ | E19: GE | F19: Dinamap Pro 1000 | G19: WAA06460043SA | H19: HI09-6515-280-0001/50.4 | I19: หอผู้ป่วยวิกฤตโรคหลอดเลือดสมอง | J19: หอผู้ป่วยวิกฤตโรคหลอดเลือดสมอง | K19: งานการพยาบาลผู้ป่วยอายุรศาสตร์ | L19: ชำรุด | M19: ชำรุด / รออะไหล่ | N19: DEFECTIVE | O19: 46294 | P19: ส่งซ่อมเครื่องมือแพทย์
A20: 19 | B20: MEDCMU-000282 | C20: Vital Sign Monitors | D20: เครื่องติดตามการทำงานของหัวใจและสัญญาณชีพ | E20: GE | F20: Dinamap Pro 1000 | G20: WAA06420006SA | H20: H09-6515-280-0001/50.3 | I20: หอผู้ป่วยวิกฤตโรคหลอดเลือดสมอง | J20: หอผู้ป่วยวิกฤตโรคหลอดเลือดสมอง | K20: งานการพยาบาลผู้ป่วยอายุรศาสตร์ | L20: คืนพัสดุ | M20: หน่วยงานแจ้งว่าคืนพัสดุแล้ว / รอเอกสารยืนยัน | N20: ยกเลิกการใช้งาน | O20: 46294
A21: 20 | B21: MEDCMU-000283 | C21: Vital Sign Monitors | D21: เครื่องติดตามการทำงานของหัวใจและสัญญาณชีพ | E21: GE | F21: IntelliVue MP20 | G21: DE72877721 | H21: DF09-6545-018-0032/56(1) | I21: หอผู้ป่วยวิกฤตโรคหลอดเลือดสมอง | J21: หอผู้ป่วยวิกฤตโรคหลอดเลือดสมอง | K21: งานการพยาบาลผู้ป่วยอายุรศาสตร์ | L21: =INDEX(จองคิว!$C:$C,MATCH('เครื่องมือแพทย์ (956)'!B21,จองคิว!$F:$F,0)) -> 46288 | M21: หน่วยงานแจ้งว่าแทงชำรุดแล้ว / รอเอกสารยืนยัน | N21: PASS | O21: 46288
A22: 21 | B22: MEDCMU-000287 | C22: Vital Sign Monitors | D22: เครื่องติดตามการทำงานของหัวใจและสัญญาณชีพ | E22: Philips | F22: IntelliVue MP20 | G22: DE72877736 | H22: DF09-6545-018-0032/56(2) | I22: หอผู้ป่วยวิกฤตโรคหลอดเลือดสมอง | J22: หอผู้ป่วยวิกฤตโรคหลอดเลือดสมอง | K22: งานการพยาบาลผู้ป่วยอายุรศาสตร์ | L22: ชำรุด | M22: ชำรุด / รออะไหล่ | N22: PASS | O22: 46288
A23: 22 | B23: MEDCMU-000301 | C23: Vital Sign Monitors | D23: เครื่องติดตามการทำงานของหัวใจและสัญญาณชีพ | E23: Philips | F23: SureSigns VM4 | G23: US94339201 | H23: HI920209-6695-021-0709/53(5) | I23: หอผู้ป่วยวิกฤตโรคหลอดเลือดสมอง | J23: หอผู้ป่วยวิกฤตโรคหลอดเลือดสมอง | K23: งานการพยาบาลผู้ป่วยอายุรศาสตร์ | L23: =INDEX(จองคิว!$C:$C,MATCH('เครื่องมือแพทย์ (956)'!B23,จองคิว!$F:$F,0)) -> 46288 | N23: PASS | O23: 46288 | P23: สาย SpO2 ชำรุดใช้ของเครื่องอื่นในการสอบเทียบ
A24: 23 | B24: MEDCMU-000388 | C24: Vital Sign Monitors | D24: เครื่องติดตามการทำงานของหัวใจและสัญญาณชีพ | E24: Edan | F24: iM20 | G24: 260374-M19205210002 | H24: DF(1)09-6545-018-0389/62(1) | I24: หน่วยตรวจสวนหัวใจและหลอดเลือด | J24: หน่วยตรวจสวนหัวใจและหลอดเลือด | K24: งานการพยาบาลผู้ป่วยอายุรศาสตร์ | L24: =INDEX(จองคิว!$C:$C,MATCH('เครื่องมือแพทย์ (956)'!B24,จองคิว!$F:$F,0)) -> 46268 | N24: PASS | O24: 46268
A25: 24 | B25: MEDCMU-000393 | C25: Pacemaker | D25: เครื่องเครื่องควบคุมจังหวะการเต้นของหัวใจ | E25: Medtronic | F25: 5348 | G25: PEP006209P | H25: 6515-345-011/4-40 1-3 | I25: หน่วยตรวจสวนหัวใจและหลอดเลือด | J25: หน่วยตรวจสวนหัวใจและหลอดเลือด | K25: งานการพยาบาลผู้ป่วยอายุรศาสตร์ | L25: =INDEX(จองคิว!$C:$C,MATCH('เครื่องมือแพทย์ (956)'!B25,จองคิว!$F:$F,0)) -> 46269 | N25: PASS | O25: 46269
A26: 25 | B26: MEDCMU-000399 | C26: Vital Sign Monitors | D26: เครื่องติดตามการทำงานของหัวใจและสัญญาณชีพ | E26: Edan | F26: iM60 | G26: 360079-M19408240001 | H26: DF(1)09-6545-018-0340/63(1) | I26: หน่วยตรวจพิเศษทางระบบหัวใจ และหลอดเลือดแบบภายนอก | J26: หน่วยตรวจพิเศษทางระบบหัวใจ และหลอดเลือดแบบภายนอก | K26: งานการพยาบาลผู้ป่วยอายุรศาสตร์ | L26: =INDEX(จองคิว!$C:$C,MATCH('เครื่องมือแพทย์ (956)'!B26,จองคิว!$F:$F,0)) -> 46268 | N26: PASS | O26: 46268 | P26: Battery เสื่อมสภาพ | R26: /
A27: 26 | B27: MEDCMU-000403 | C27: Electrosurgical Unit | D27: เครื่องจี้และตัดด้วยไฟฟ้า | E27: Erbe | F27: Vio 100 C | G27: 11309574 | H27: DF(1)09-6695-021-0831/52(1) | I27: หน่วยตรวจสวนหัวใจและหลอดเลือด | J27: หน่วยตรวจสวนหัวใจและหลอดเลือด | K27: งานการพยาบาลผู้ป่วยอายุรศาสตร์ | L27: =INDEX(จองคิว!$C:$C,MATCH('เครื่องมือแพทย์ (956)'!B27,จองคิว!$F:$F,0)) -> 46268 | N27: OUT OF RANGE | O27: 46268 | P27: สอบเทียบไม่ผ่าน ค่า Bipolar ต่ำกว่าเกณฑ์ (+-20% : 10 = 5)
A28: 27 | B28: MEDCMU-000406 | C28: Vital Sign Monitors | D28: เครื่องติดตามการทำงานของหัวใจและสัญญาณชีพ | E28: Philips | F28: SureSigns VM4 | G28: US90328532 | H28: HI920209-6695-021-0815/52(2) | I28: หน่วยตรวจสวนหัวใจและหลอดเลือด | J28: หน่วยตรวจสวนหัวใจและหลอดเลือด | K28: งานการพยาบาลผู้ป่วยอายุรศาสตร์ | L28: =INDEX(จองคิว!$C:$C,MATCH('เครื่องมือแพทย์ (956)'!B28,จองคิว!$F:$F,0)) -> 46268 | N28: PASS | O28: 46268
A29: 28 | B29: MEDCMU-000407 | C29: Vital Sign Monitors | D29: เครื่องติดตามการทำงานของหัวใจและสัญญาณชีพ | E29: Philips | F29: SureSigns VM4 | G29: US90328524 | H29: HI920209-6695-021-0815/52(1) | I29: หน่วยตรวจสวนหัวใจและหลอดเลือด | J29: หน่วยตรวจสวนหัวใจและหลอดเลือด | K29: งานการพยาบาลผู้ป่วยอายุรศาสตร์ | L29: =INDEX(จองคิว!$C:$C,MATCH('เครื่องมือแพทย์ (956)'!B29,จองคิว!$F:$F,0)) -> 46269 | N29: PASS | O29: 46269 | P29: AC Plug ขา Ground หัก เปลี่ยนสายไฟเส้นใหม่เรียบร้อย | Q29: /
A30: 29 | B30: MEDCMU-000408 | C30: Vital Sign Monitors | D30: เครื่องติดตามการทำงานของหัวใจและสัญญาณชีพ | E30: Goldway | F30: G30E | G30: CN50803278 | H30: HI220209-6545-018-0243/61(2) | I30: หน่วยตรวจสวนหัวใจและหลอดเลือด | J30: หน่วยตรวจสวนหัวใจและหลอดเลือด | K30: งานการพยาบาลผู้ป่วยอายุรศาสตร์ | L30: =INDEX(จองคิว!$C:$C,MATCH('เครื่องมือแพทย์ (956)'!B30,จองคิว!$F:$F,0)) -> 46269 | N30: PASS | O30: 46269
A31: 30 | B31: MEDCMU-000409 | C31: Vital Sign Monitors | D31: เครื่องติดตามการทำงานของหัวใจและสัญญาณชีพ | E31: Goldway | F31: G30E | G31: CN50803282 | H31: HI920209-6545-018-0243/61(3) | I31: หน่วยตรวจสวนหัวใจและหลอดเลือด | J31: หน่วยตรวจสวนหัวใจและหลอดเลือด | K31: งานการพยาบาลผู้ป่วยอายุรศาสตร์ | L31: =INDEX(จองคิว!$C:$C,MATCH('เครื่องมือแพทย์ (956)'!B31,จองคิว!$F:$F,0)) -> 46272 | N31: PASS | O31: 46272
A32: 31 | B32: MEDCMU-000410 | C32: Vital Sign Monitors | D32: เครื่องติดตามการทำงานของหัวใจและสัญญาณชีพ | E32: Goldway | F32: G30E | G32: CN50803299 | H32: HI920209-6545-018-0243/61(1) | I32: หน่วยตรวจสวนหัวใจและหลอดเลือด | J32: หน่วยตรวจสวนหัวใจและหลอดเลือด | K32: งานการพยาบาลผู้ป่วยอายุรศาสตร์ | L32: =INDEX(จองคิว!$C:$C,MATCH('เครื่องมือแพทย์ (956)'!B32,จองคิว!$F:$F,0)) -> 46272 | N32: PASS | O32: 46272
A33: 32 | B33: MEDCMU-000441 | C33: Vital Sign Monitors | D33: เครื่องติดตามการทำงานของหัวใจและสัญญาณชีพ | E33: Lutech | F33: Datalys 760 | G33: KD180626016 | H33: DF0409-6545-018-0451/62(4) | I33: หน่วยตรวจพิเศษทางระบบหัวใจ และหลอดเลือดแบบภายนอก | J33: หน่วยตรวจพิเศษทางระบบหัวใจ และหลอดเลือดแบบภายนอก | K33: งานการพยาบาลผู้ป่วยอายุรศาสตร์ | L33: =INDEX(จองคิว!$C:$C,MATCH('เครื่องมือแพทย์ (956)'!B33,จองคิว!$F:$F,0)) -> 46268 | N33: PASS | O33: 46268 | P33: Battery เสื่อมสภาพ | R33: /
A34: 33 | B34: MEDCMU-000454 | C34: Vital Sign Monitors | D34: เครื่องติดตามการทำงานของหัวใจและสัญญาณชีพ | E34: Philips | F34: SureSigns VM4 | G34: US94347182 | H34: HI920209-6670-001-0273/54(3) | I34: หน่วยตรวจพิเศษทางระบบหัวใจ และหลอดเลือดแบบภายนอก | J34: หน่วยตรวจพิเศษทางระบบหัวใจ และหลอดเลือดแบบภายนอก | K34: งานการพยาบาลผู้ป่วยอายุรศาสตร์ | L34: =INDEX(จองคิว!$C:$C,MATCH('เครื่องมือแพทย์ (956)'!B34,จองคิว!$F:$F,0)) -> 46268 | N34: PASS | O34: 46268 | P34: ไม่ได้สอบเทียบโหมด EKG เนื่องจากไม่มีสายและแผนกไม่ได้ใช้งานโหมดนี้
A35: 34 | B35: MEDCMU-000553 | C35: Electrocardiography | D35: เครื่องตรวจวิเคราะห์คลื่นไฟฟ้าหัวใจ | E35: Philips | F35: PageWriter TC10 | G35: CN01702979 | H35: DF0409-6545-018-0387/61(1) | I35: หอผู้ป่วยหนักโรคหัวใจและหลอดเลือด 1 | J35: หอผู้ป่วยหนักโรคหัวใจและหลอดเลือด 1 | K35: งานการพยาบาลผู้ป่วยอายุรศาสตร์ | L35: =INDEX(จองคิว!$C:$C,MATCH('เครื่องมือแพทย์ (956)'!B35,จองคิว!$F:$F,0)) -> 46279 | N35: PASS | O35: 46279 | P35: Battery เสื่อมสภาพ | R35: /
A36: 35 | B36: MEDCMU-000554 | C36: Electrocardiography | D36: เครื่องตรวจวิเคราะห์คลื่นไฟฟ้าหัวใจ | E36: Nihon Kohden | F36: Cardiofax M | G36: 112588 | H36: HI920209-6545-018-0384/62(1) | I36: หอผู้ป่วยหนักโรคหัวใจและหลอดเลือด 1 | J36: หอผู้ป่วยหนักโรคหัวใจและหลอดเลือด 1 | K36: งานการพยาบาลผู้ป่วยอายุรศาสตร์ | L36: =INDEX(จองคิว!$C:$C,MATCH('เครื่องมือแพทย์ (956)'!B36,จองคิว!$F:$F,0)) -> 46279 | N36: PASS | O36: 46279
A37: 36 | B37: MEDCMU-000555 | C37: Vital Sign Monitors | D37: เครื่องติดตามการทำงานของหัวใจและสัญญาณชีพ | E37: Philips | F37: IntelliVue MP20 | G37: DE72838269 | H37: HI09-6515-021-0008/51(1) | I37: หอผู้ป่วยหนักโรคหัวใจและหลอดเลือด 1 | J37: หอผู้ป่วยหนักโรคหัวใจและหลอดเลือด 1 | K37: งานการพยาบาลผู้ป่วยอายุรศาสตร์ | L37: =INDEX(จองคิว!$C:$C,MATCH('เครื่องมือแพทย์ (956)'!B37,จองคิว!$F:$F,0)) -> 46279 | N37: PASS | O37: 46279
A38: 37 | B38: MEDCMU-000556 | C38: Vital Sign Monitors | D38: เครื่องติดตามการทำงานของหัวใจและสัญญาณชีพ | E38: Philips | F38: IntelliVue X2 | G38: DE83635001 | H38: HI920209-6695-021-0928/53(3) | I38: หอผู้ป่วยหนักโรคหัวใจและหลอดเลือด 1 | J38: หอผู้ป่วยหนักโรคหัวใจและหลอดเลือด 1 | K38: งานการพยาบาลผู้ป่วยอายุรศาสตร์ | L38: =INDEX(จองคิว!$C:$C,MATCH('เครื่องมือแพทย์ (956)'!B38,จองคิว!$F:$F,0)) -> 46279 | N38: PASS | O38: 46279 | P38: กรอบตัวเครื่องแตก
A39: 38 | B39: MEDCMU-000558 | C39: Vital Sign Monitors | D39: เครื่องติดตามการทำงานของหัวใจและสัญญาณชีพ | E39: Philips | F39: IntelliVue MP60 | G39: DE73113114 | H39: HI09-6515-021-0008/51(1) | I39: หอผู้ป่วยหนักโรคหัวใจและหลอดเลือด 1 | J39: หอผู้ป่วยหนักโรคหัวใจและหลอดเลือด 1 | K39: งานการพยาบาลผู้ป่วยอายุรศาสตร์ | L39: =INDEX(จองคิว!$C:$C,MATCH('เครื่องมือแพทย์ (956)'!B39,จองคิว!$F:$F,0)) -> 46279 | N39: PASS | O39: 46279 | P39: ไม่ได้วัดค่า Electrical Safety เนื่องจากติดใช้งานกับคนใช้
A40: 39 | B40: MEDCMU-000575 | C40: Pacemaker | D40: เครื่องเครื่องควบคุมจังหวะการเต้นของหัวใจ | E40: Medtronic | F40: 5348 | G40: PEP031798P | H40: HI09-6515-345-0021/51(1) | I40: หอผู้ป่วยหนักโรคหัวใจและหลอดเลือด 1 | J40: หอผู้ป่วยหนักโรคหัวใจและหลอดเลือด 1 | K40: งานการพยาบาลผู้ป่วยอายุรศาสตร์ | L40: =INDEX(จองคิว!$C:$C,MATCH('เครื่องมือแพทย์ (956)'!B40,จองคิว!$F:$F,0)) -> 46279 | N40: PASS | O40: 46279
...

Sheet Sheet2
A1: จองคิว | B1: #N/A
A3: ป้ายชื่อแถว | B3: นับจำนวน ของ รหัสเครื่อง
A4: งานการพยาบาลผู้ป่วยกุมารเวชศาสตร์ | B4: 72
A5: หอผู้ป่วยกุมารเวชกรรม 2 | B5: 8
A6: หอผู้ป่วยกุมารเวชกรรม 3 | B6: 10
A7: หอผู้ป่วยกุมารเวชกรรม 4 | B7: 2
A8: หอผู้ป่วยทารกแรกเกิด 2 | B8: 15
A9: หอผู้ป่วยวิกฤตทารกแรกเกิด | B9: 8
A10: หอผู้ป่วยหนักกุมารเวชกรรม | B10: 1
A11: หอผู้ป่วยหนักกุมารเวชกรรมหัวใจ | B11: 2
A12: หอผู้ป่วยหนักทารกแรกเกิด 2 | B12: 26
A13: งานการพยาบาลผู้ป่วยนอกและผู้ป่วยฉุกเฉิน | B13: 26
A14: EID clinic | B14: 2
A15: หน่วยเคมีบำบัดผู้ป่วยนอก 1 | B15: 1
... A69: ผลรวมทั้งหมด | B69: 316

Sheet คิวว่าง
A3: Count of รหัสเครื่อง | B3: Column Labels | U3: จำนวนคิวว่าง (เครื่อง)
A4: Row Labels | B4: #N/A | C4: (blank) | D4: Vital Sign Monitors | E4: Electrocardiography | F4: Pulse Oximeter | G4: Electrosurgical Unit | H4: Vital Sign Monitors, BedSide | I4: Drop tone,Doppler | J4: Fetal Monitors | K4: Infant Incubator | L4: Radiant Warmer | M4: Pacemaker | N4: Blood Flow Detector,Doppler | O4: Harmonic Electrosurgical Unit | P4: Infant Incubator,Transport | Q4: Grand Total | U4: =NOW() -> 46297.421
A5: 46267 | D5: 27 | E5: 3 | F5: 15 | G5: 2 | H5: 2 | Q5: 49 | U5: จันทร์ | V5: อังคาร | W5: พุธ | X5: พฤหัสบดี | Y5: ศุกร์ | Z5: เสาร์ | AA5: อาทิตย์
A6: 46268 | D6: 30 | E6: 3 | F6: 11 | G6: 3 | I6: 1 | Q6: 48 | W6: 46267 | X6: 46268 | Y6: 46269 | Z6: 46270 | AA6: 46271
A7: 46269 | D7: 28 | E7: 2 | F7: 11 | G7: 1 | I7: 2 | J7: 2 | M7: 2 | N7: 1 | Q7: 49 | W7: =IF(W8=0,"เต็มแล้ว","ว่าง") -> เต็มแล้ว | X7: =IF(X8=0,"เต็มแล้ว","ว่าง") -> เต็มแล้ว | Y7: =IF(Y8=0,"เต็มแล้ว","ว่าง") -> เต็มแล้ว
A8: 46272 | D8: 32 | E8: 3 | F8: 5 | G8: 1 | H8: 1 | I8: 1 | K8: 5 | L8: 1 | M8: 4 | Q8: 53 | W8: =+GETPIVOTDATA("รหัสเครื่อง",$A$3,"นัดหมาย",DATE(2026,9,2),"ชื่อเครื่อง",#N/A) -> 0 | X8: =+GETPIVOTDATA("รหัสเครื่อง",$A$3,"นัดหมาย",DATE(2026,9,3),"ชื่อเครื่อง",#N/A) -> 0 | Y8: =+GETPIVOTDATA("รหัสเครื่อง",$A$3,"นัดหมาย",DATE(2026,9,4),"ชื่อเครื่อง",#N/A) -> 0
A9: 46273 | D9: 34 | E9: 2 | F9: 6 | H9: 5 | I9: 1 | M9: 1 | Q9: 49
A10: 46274 | D10: 38 | E10: 4 | F10: 3 | G10: 1 | H10: 1 | I10: 2 | J10: 1 | L10: 1 | M10: 3 | Q10: 54 | U10: 46272 | V10: 46273 | W10: 46274 | X10: 46275 | Y10: 46276 | Z10: 46277 | AA10: 46278
A11: 46275 | D11: 31 | E11: 3 | F11: 22 | G11: 1 | I11: 3 | Q11: 60 | U11: =IF(U12=0,"เต็มแล้ว","ว่าง") -> เต็มแล้ว | V11: =IF(V12=0,"เต็มแล้ว","ว่าง") -> เต็มแล้ว | W11: =IF(W12=0,"เต็มแล้ว","ว่าง") -> เต็มแล้ว | X11: =IF(X12=0,"เต็มแล้ว","ว่าง") -> เต็มแล้ว | Y11: =IF(Y12=0,"เต็มแล้ว","ว่าง") -> ว่าง | Z11: =IF(Z12=0,"เต็มแล้ว","ว่าง") -> เต็มแล้ว | AA11: =IF(AA12=0,"เต็มแล้ว","ว่าง") -> เต็มแล้ว
A12: 46276 | B12: 2 | D12: 20 | E12: 3 | F12: 10 | G12: 1 | H12: 13 | I12: 2 | Q12: 51 | U12: =+GETPIVOTDATA("รหัสเครื่อง",$A$3,"นัดหมาย",DATE(2026,9,7),"ชื่อเครื่อง",#N/A) -> 0 | V12: =+GETPIVOTDATA("รหัสเครื่อง",$A$3,"นัดหมาย",DATE(2026,9,8),"ชื่อเครื่อง",#N/A) -> 0 | W12: =+GETPIVOTDATA("รหัสเครื่อง",$A$3,"นัดหมาย",DATE(2026,9,9),"ชื่อเครื่อง",#N/A) -> 0 | X12: =+GETPIVOTDATA("รหัสเครื่อง",$A$3,"นัดหมาย",DATE(2026,9,10),"ชื่อเครื่อง",#N/A) -> 0 | Y12: =+GETPIVOTDATA("รหัสเครื่อง",$A$3,"นัดหมาย",DATE(2026,9,11),"ชื่อเครื่อง",#N/A) -> 2 | Z12: =+GETPIVOTDATA("รหัสเครื่อง",$A$3,"นัดหมาย",DATE(2026,9,12),"ชื่อเครื่อง",#N/A) -> 0 | AA12: =+GETPIVOTDATA("รหัสเครื่อง",$A$3,"นัดหมาย",DATE(2026,9,13),"ชื่อเครื่อง",#N/A) -> 0
A13: 46279 | B13: 4 | D13: 35 | E13: 4 | F13: 2 | H13: 4 | M13: 5 | Q13: 54
A14: 46280 | B14: 3 | D14: 32 | E14: 7 | F14: 7 | G14: 3 | L14: 1 | P14: 1 | Q14: 54 | U14: 46279 | V14: 46280 | W14: 46281 | X14: 46282 | Y14: 46283 | Z14: 46284 | AA14: 46285
A15: 46281 | B15: 3 | D15: 27 | E15: 9 | F15: 7 | I15: 3 | J15: 1 | Q15: 50 | U15: =IF(U16=0,"เต็มแล้ว","ว่าง") -> ว่าง | V15: =IF(V16=0,"เต็มแล้ว","ว่าง") -> ว่าง | W15: =IF(W16=0,"เต็มแล้ว","ว่าง") -> ว่าง | X15: =IF(X16=0,"เต็มแล้ว","ว่าง") -> ว่าง | Y15: =IF(Y16=0,"เต็มแล้ว","ว่าง") -> เต็มแล้ว
A16: 46282 | B16: 5 | D16: 17 | E16: 1 | F16: 5 | K16: 5 | L16: 17 | Q16: 50 | U16: =+GETPIVOTDATA("รหัสเครื่อง",$A$3,"นัดหมาย",DATE(2026,9,14),"ชื่อเครื่อง",#N/A) -> 4 | V16: =+GETPIVOTDATA("รหัสเครื่อง",$A$3,"นัดหมาย",DATE(2026,9,15),"ชื่อเครื่อง",#N/A) -> 3 | W16: =+GETPIVOTDATA("รหัสเครื่อง",$A$3,"นัดหมาย",DATE(2026,9,16),"ชื่อเครื่อง",#N/A) -> 3 | X16: =+GETPIVOTDATA("รหัสเครื่อง",$A$3,"นัดหมาย",DATE(2026,9,17),"ชื่อเครื่อง",#N/A) -> 5 | Y16: =+GETPIVOTDATA("รหัสเครื่อง",$A$3,"นัดหมาย",DATE(2026,9,18),"ชื่อเครื่อง",#N/A) -> 0
A17: 46283 | D17: 36 | E17: 4 | F17: 8 | G17: 1 | I17: 1 | Q17: 50
A18: 46286 | B18: 1 | D18: 31 | E18: 2 | F18: 1 | I18: 5 | J18: 5 | K18: 3 | L18: 2 | Q18: 50 | U18: 46286 | V18: 46287 | W18: 46288 | X18: 46289 | Y18: 46290 | Z18: 46291 | AA18: 46292
A19: 46287 | B19: 5 | D19: 19 | E19: 1 | F19: 6 | H19: 7 | I19: 3 | J19: 6 | K19: 2 | L19: 1 | Q19: 50 | U19: =IF(U20=0,"เต็มแล้ว","ว่าง") -> ว่าง | V19: =IF(V20=0,"เต็มแล้ว","ว่าง") -> ว่าง | W19: =IF(W20=0,"เต็มแล้ว","ว่าง") -> ว่าง | X19: =IF(X20=0,"เต็มแล้ว","ว่าง") -> ว่าง | Y19: =IF(Y20=0,"เต็มแล้ว","ว่าง") -> ว่าง
A20: 46288 | B20: 2 | D20: 32 | E20: 3 | F20: 7 | K20: 4 | L20: 2 | Q20: 50 | U20: =+GETPIVOTDATA("รหัสเครื่อง",$A$3,"นัดหมาย",DATE(2026,9,21),"ชื่อเครื่อง",#N/A) -> 1 | V20: =+GETPIVOTDATA("รหัสเครื่อง",$A$3,"นัดหมาย",DATE(2026,9,22),"ชื่อเครื่อง",#N/A) -> 5 | W20: =+GETPIVOTDATA("รหัสเครื่อง",$A$3,"นัดหมาย",DATE(2026,9,23),"ชื่อเครื่อง",#N/A) -> 2 | X20: =+GETPIVOTDATA("รหัสเครื่อง",$A$3,"นัดหมาย",DATE(2026,9,24),"ชื่อเครื่อง",#N/A) -> 50 | Y20: =+GETPIVOTDATA("รหัสเครื่อง",$A$3,"นัดหมาย",DATE(2026,9,25),"ชื่อเครื่อง",#N/A) -> 47
A21: 46289 | B21: 50 | Q21: 50
A22: 46290 | B22: 47 | E22: 2 | F22: 1 | Q22: 50 | U22: 46293 | V22: 46294 | W22: 46295
A23: 46293 | B23: 31 | D23: 12 | H23: 7 | Q23: 50 | U23: =IF(U24=0,"เต็มแล้ว","ว่าง") -> ว่าง | V23: =IF(V24=0,"เต็มแล้ว","ว่าง") -> ว่าง | W23: =IF(W24=0,"เต็มแล้ว","ว่าง") -> ว่าง
A24: 46294 | B24: 50 | Q24: 50 | U24: =+GETPIVOTDATA("รหัสเครื่อง",$A$3,"นัดหมาย",DATE(2026,9,28),"ชื่อเครื่อง",#N/A) -> 31 | V24: =+GETPIVOTDATA("รหัสเครื่อง",$A$3,"นัดหมาย",DATE(2026,9,29),"ชื่อเครื่อง",#N/A) -> 50 | W24: =+GETPIVOTDATA("รหัสเครื่อง",$A$3,"นัดหมาย",DATE(2026,9,30),"ชื่อเครื่อง",#N/A) -> 40
A25: 46295 | B25: 40 | D25: 1 | F25: 2 | G25: 7 | Q25: 50
A26: (blank)
A27: 46277 | D27: 9 | F27: 8 | G27: 26 | N27: 1 | O27: 3 | Q27: 47
A28: 46278 | D28: 41 | F28: 7 | L28: 2 | M28: 2 | Q28: 52
A29: Grand Total | B29: 243 | D29: 532 | E29: 56 | F29: 144 | G29: 47 | H29: 40 | I29: 24 | J29: 15 | K29: 19 | L29: 27 | M29: 17 | N29: 2 | O29: 3 | P29: 1 | Q29: 1170

Sheet เรียกคิว
A1: ลำดับ | B1: รหัสเครื่อง | C1: ชื่อเครื่อง | D1: ชื่อเครื่องภาษาไทย | E1: ยี่ห้อ | F1: รุ่น | G1: SerialNo | H1: เลขครุภัณฑ์ | I1: ชื่อหน่วยงานเจ้าของเครื่อง | J1: ชื่อหน่วยงานที่ใช้เครื่อง | K1: งาน
A2: 1 | B2: MEDCMU-000022 | C2: Vital Sign Monitors | D2: เครื่องติดตามการทำงานของหัวใจและสัญญาณชีพ | E2: Philips | F2: Efficia CM10 | G2: CN62637717 | H2: DF(1)09-6515-026-0023/62(6) | I2: หอผู้ป่วยปลูกถ่ายไขกระดูกและให้เคมีบำบัดขนาดสูง | J2: หอผู้ป่วยปลูกถ่ายไขกระดูกและให้เคมีบำบัดขนาดสูง | K2: งานการพยาบาลผู้ป่วยอายุรศาสตร์
A3: 2 | B3: MEDCMU-000040 | C3: Electrocardiography | D3: เครื่องตรวจวิเคราะห์คลื่นไฟฟ้าหัวใจ | E3: Philips | F3: PageWriter TC10 | G3: CNN1810996 | H3: DF(1)09-6545-018-0262/62(1) | I3: หอผู้ป่วยปลูกถ่ายไขกระดูกและให้เคมีบำบัดขนาดสูง | J3: หอผู้ป่วยปลูกถ่ายไขกระดูกและให้เคมีบำบัดขนาดสูง | K3: งานการพยาบาลผู้ป่วยอายุรศาสตร์
A4: 3 | B4: MEDCMU-000046 | C4: Vital Sign Monitors | D4: เครื่องติดตามการทำงานของหัวใจและสัญญาณชีพ | E4: Philips | F4: Efficia CM10 | G4: CN62637715 | H4: DF(1)09-6515-026-0023/62(3) | I4: หอผู้ป่วยปลูกถ่ายไขกระดูกและให้เคมีบำบัดขนาดสูง | J4: หอผู้ป่วยปลูกถ่ายไขกระดูกและให้เคมีบำบัดขนาดสูง | K4: งานการพยาบาลผู้ป่วยอายุรศาสตร์
A5: 4 | B5: MEDCMU-000049 | C5: Vital Sign Monitors | D5: เครื่องติดตามการทำงานของหัวใจและสัญญาณชีพ | E5: Philips | F5: Efficia CM10 | G5: CN62637713 | H5: DF(1)09-6515-026-0023/62(5) | I5: หอผู้ป่วยปลูกถ่ายไขกระดูกและให้เคมีบำบัดขนาดสูง | J5: หอผู้ป่วยปลูกถ่ายไขกระดูกและให้เคมีบำบัดขนาดสูง | K5: งานการพยาบาลผู้ป่วยอายุรศาสตร์
A6: 5 | B6: MEDCMU-000055 | C6: Vital Sign Monitors | D6: เครื่องติดตามการทำงานของหัวใจและสัญญาณชีพ | E6: Bionet | F6: BM5 | G6: D8O040021 | H6: HI920209-6515-026-0003/56(18) | I6: หอผู้ป่วยปลูกถ่ายไขกระดูกและให้เคมีบำบัดขนาดสูง | J6: หอผู้ป่วยปลูกถ่ายไขกระดูกและให้เคมีบำบัดขนาดสูง | K6: งานการพยาบาลผู้ป่วยอายุรศาสตร์
A7: 6 | B7: MEDCMU-000057 | C7: Vital Sign Monitors | D7: เครื่องติดตามการทำงานของหัวใจและสัญญาณชีพ | E7: Philips | F7: Efficia CM10 | G7: CN62635735 | H7: DF(1)09-6515-026-0023/62(7) | I7: หอผู้ป่วยปลูกถ่ายไขกระดูกและให้เคมีบำบัดขนาดสูง | J7: หอผู้ป่วยปลูกถ่ายไขกระดูกและให้เคมีบำบัดขนาดสูง | K7: งานการพยาบาลผู้ป่วยอายุรศาสตร์
A8: 7 | B8: MEDCMU-000070 | C8: Vital Sign Monitors | D8: เครื่องติดตามการทำงานของหัวใจและสัญญาณชีพ | E8: Bionet | F8: BM5 | G8: D8O0600071 | H8: HI920209-6515-026-0003/57(8) | I8: หอผู้ป่วยปลูกถ่ายไขกระดูกและให้เคมีบำบัดขนาดสูง | J8: หอผู้ป่วยปลูกถ่ายไขกระดูกและให้เคมีบำบัดขนาดสูง | K8: งานการพยาบาลผู้ป่วยอายุรศาสตร์
A9: 8 | B9: MEDCMU-000076 | C9: Vital Sign Monitors | D9: เครื่องติดตามการทำงานของหัวใจและสัญญาณชีพ | E9: Philips | F9: Efficia CM10 | G9: CN62637716 | H9: DF(1)09-6515-026-0023/62(2) | I9: หอผู้ป่วยปลูกถ่ายไขกระดูกและให้เคมีบำบัดขนาดสูง | J9: หอผู้ป่วยปลูกถ่ายไขกระดูกและให้เคมีบำบัดขนาดสูง | K9: งานการพยาบาลผู้ป่วยอายุรศาสตร์
A10: 9 | B10: MEDCMU-000082 | C10: Vital Sign Monitors | D10: เครื่องติดตามการทำงานของหัวใจและสัญญาณชีพ | E10: Philips | F10: Efficia CM10 | G10: CN62637714 | H10: DF(1)09-6515-026-0023/62(4) | I10: หอผู้ป่วยปลูกถ่ายไขกระดูกและให้เคมีบำบัดขนาดสูง | J10: หอผู้ป่วยปลูกถ่ายไขกระดูกและให้เคมีบำบัดขนาดสูง | K10: งานการพยาบาลผู้ป่วยอายุรศาสตร์
A11: 10 | B11: MEDCMU-000101 | C11: Vital Sign Monitors | D11: เครื่องติดตามการทำงานของหัวใจและสัญญาณชีพ | E11: Philips | F11: Efficia CM100 | G11: CN62626250 | H11: DF0409-6545-018-0211/59(5) | I11: หน่วยเปลี่ยนไตและไตเทียม | J11: หน่วยเปลี่ยนไตและไตเทียม | K11: งานการพยาบาลผู้ป่วยอายุรศาสตร์
A12: 11 | B12: MEDCMU-000102 | C12: Vital Sign Monitors | D12: เครื่องติดตามการทำงานของหัวใจและสัญญาณชีพ | E12: Philips | F12: Efficia CM100 | G12: CN62626316 | H12: DF0409-6545-018-0211/59(7) | I12: หน่วยเปลี่ยนไตและไตเทียม | J12: หน่วยเปลี่ยนไตและไตเทียม | K12: งานการพยาบาลผู้ป่วยอายุรศาสตร์
A13: 12 | B13: MEDCMU-000103 | C13: Vital Sign Monitors | D13: เครื่องติดตามการทำงานของหัวใจและสัญญาณชีพ | E13: Philips | F13: Efficia CM100 | G13: CN62626241 | H13: DF0409-6545-018-0211/59(6) | I13: หน่วยเปลี่ยนไตและไตเทียม | J13: หน่วยเปลี่ยนไตและไตเทียม | K13: งานการพยาบาลผู้ป่วยอายุรศาสตร์
